Workbook
Name base_year: 'Cover Page'!$F$15
Name bs_check: '3-Statement'!$F$104
Name circularity: 'Cover Page'!$F$19
Name company_name: 'Cover Page'!$C$5
Name money: Inputs!$E$13

Sheet Cover Page
C5: BT GROUP PLC
C6: BT.L
C8: Author: | F8: Opeoluwa Kuku
C9: School ID: | F9: H00529768
C10: Course: | F10: Corporate Finance
C11: Course Code: | F11: C31CF
C12: Scalling: | F12: Millions GBP
C13: Historical Period: | F13: 31/Mar/2022 - 31/Mar/2026
C14: Forecast Period: | F14: 31/Mar/2027 - 31/Mar/2031
C15: Base Year: | F15: 2026
C16: Valuation Date: | F16: 46319
C17: Current Share Price: | F17: 211.8 | U17: Do Not delete
C18: Balance Sheet: | F18: =IF(bs_check=0,"Balanced","Error!!!") -> Balanced | U18: 1
C19: Circularity: | F19: 1 | U19: 0

Sheet Investment recommendation
B2: =company_name -> BT GROUP PLC
C3: Investment Recommendation
B8: Dashboard
D10: ="Current Share Price: "&'Cover Page'!F17 -> Current Share Price: 211.8
D11: Recommendation: Buy
D12: Date | E12: ='Cover Page'!F16 -> 46319
D13: Valuation Summary | V13: Valuation Ranges
V41: Data
Z43: High | AA43: Mid | AB43: Low
V44: =D56 -> Dividend Discount Model | Z44: =G71 -> 157.46247 | AA44: =I72 -> 128.29569 | AB44: =K74 -> 103.70133
V45: =D57 -> FCFF/FCFE Model | Z45: =W71 -> 434.17676 | AA45: =X73 -> 319.75487 | AB45: =Z74 -> 227.66208
V46: =D58 -> Residual Income | Z46: =O71 -> 314.26293 | AA46: =Q72 -> 254.41506 | AB46: =S74 -> 210.59713
V47: =D59 -> Comparables | Z47: =W56 -> 376.62783 | AA47: =W57 -> 225.95691 | AB47: =W58 -> 136.80467
C50: Inputs & Outputs
D53: Main Outputs | N53: Main Inputs | T53: Comparables (P/E)
W55: Share price/share
D56: Dividend Discount Model | E56: Pence/Sh | F56: =DDM!F43 -> 128.29569 | N56: WACC | P56: % | Q56: ='Cost of Capital'!I17 -> 0.068424935 | T56: =COMPS!C16 -> Maximum | U56: x | V56: =COMPS!F16 -> 23.850831 | W56: =V56*$V$59*100 -> 376.62783
D57: FCFF/FCFE Model | E57: Pence/Sh | F57: =FCFF!F48 -> 319.75487 | N57: Cost of Equity | P57: % | Q57: ='Cost of Equity'!E15 -> 0.092604508 | T57: =COMPS!C17 -> Average | U57: x | V57: =COMPS!F17 -> 14.309245 | W57: =V57*$V$59*100 -> 225.95691
D58: Residual Income | E58: Pence/Sh | F58: ='RES.INC'!F62 -> 254.41506 | N58: Perpetual Growth Rate | P58: % | Q58: =DDM!F17 -> 0.020296084 | T58: =COMPS!C19 -> Minimum | U58: x | V58: =COMPS!F19 -> 8.6634731 | W58: =V58*$V$59*100 -> 136.80467
D59: Comparables | E59: Pence/Sh | F59: =COMPS!I35 -> 225.95691 | N59: UK GDP Growth Rate | P59: % | Q59: =Inputs!F32 -> 0.014 | T59: =COMPS!G34 -> Forward EPS | U59: =COMPS!H34 -> [£'M] | V59: =COMPS!I34 -> 0.15790973
N60: Current Share Price | P60: Pence/Sh | Q60: ='Cover Page'!F17 -> 211.8
C64: Sensitivity
G67: Dividend Discount Model | N67: Residual Income | V67: FCFF/FCFE Model
G69: Cost of Equity | N69: Cost of Equity | W69: WACC
F70: =DDM!F43 -> 128.29569 | G70: 0.083 | H70: 0.088 | I70: 0.092604508 | J70: 0.098 | K70: 0.103 | M70: Growth Rate | N70: ='RES.INC'!F62 -> 254.41506 | O70: 0.082604508 | P70: 0.087604508 | Q70: 0.092604508 | R70: 0.097604508 | S70: 0.10260451 | U70: Growth Rate | V70: =FCFF!F48 -> 319.75487 | W70: 0.063424935 | X70: 0.068424935 | Y70: 0.073424935 | Z70: 0.078424935
E71: Growth Rate | F71: 0.025296084 | G71: 157.46247 | H71: 145.23713 | I71: 135.58494 | J71: 125.82992 | K71: 117.99898 | N71: 0.025296084 | O71: 314.26293 | P71: 286.26707 | Q71: 262.42698 | R71: 241.87968 | S71: 223.98549 | V71: 0.02 | W71: 434.17676 | X71: 371.20253 | Y71: 320.03836 | Z71: 277.65164
F72: 0.020296084 | G72: 147.35287 | H72: 136.75723 | I72: 128.29569 | J72: 119.65653 | K72: 112.65684 | N72: 0.020296084 | O72: 301.2184 | P72: 276.07842 | Q72: 254.41506 | R72: 235.55285 | S72: 218.9805 | V72: 0.017 | W72: 399.99658 | X72: 343.97803 | Y72: 297.90954 | Z72: 259.36079
F73: 0.015296084 | G73: 138.73647 | H73: 129.44369 | I73: 121.94932 | J73: 114.22958 | K73: 107.92381 | N73: 0.015296084 | O73: 290.11188 | P73: 267.29883 | Q73: 247.4395 | R73: 229.9947 | S73: 214.54876 | V73: 0.014 | W73: 369.96575 | X73: 319.75487 | Y73: 278.01501 | Z73: 242.7734
F74: 0.010296084 | G74: 131.30521 | H74: 123.07135 | I74: 116.374 | J74: 109.42141 | K74: 103.70133 | N74: 0.010296084 | O74: 280.54136 | P74: 259.65489 | Q74: 241.31143 | R74: 225.07315 | S74: 210.59713 | V74: 0.011 | W74: 343.37192 | X74: 298.06264 | Y74: 260.03266 | Z74: 227.66208

Sheet Inputs
B2: =company_name -> BT GROUP PLC
C3: Inputs and Assumptions
C5: ="Balance Sheet Check: "&IF(bs_check=0,"Balanced as all things should be","Error!!!") -> Balance Sheet Check: Balanced as all things should be
D6: Description | E6: Units | F6: Inputs | I6: Hist | J6: Hist | K6: Hist | L6: Hist | M6: Hist | N6: Forecast | O6: Forecast | P6: Forecast | Q6: Forecast | R6: Forecast | S6: Term
I7: 2022 | J7: 2023 | K7: 2024 | L7: 2025 | M7: =base_year -> 2026 | N7: =M7+1 -> 2027 | O7: =N7+1 -> 2028 | P7: =O7+1 -> 2029 | Q7: =P7+1 -> 2030 | R7: =Q7+1 -> 2031
C9: Style Guide & Timing assumption
D10: Historicals | E10: 1234
D11: Inputs | E11: 1234
D12: Linked Cells | E12: 1234 | M12: Valuation | N12: Discrete Period | S12: Term
D13: Units | E13: [£'M] | M13: (YYYY-MM-DD) | N13: (YYYY-MM-DD) | O13: (YYYY-MM-DD) | P13: (YYYY-MM-DD) | Q13: (YYYY-MM-DD) | R13: (YYYY-MM-DD)
D14: Notes | E14: Statement | M14: ='Cover Page'!F16 -> 46319 | N14: 46477 | O14: =EDATE(N14,12) -> 46843 | P14: =EDATE(O14,12) -> 47208 | Q14: =EDATE(P14,12) -> 47573 | R14: =EDATE(Q14,12) -> 47938
D15: Numbers | E15: 1234
D16: Percent | E16: 0.121
D17: Sub total | E17: 1234
D18: Total | E18: 12.35
D19: Multiples | E19: 12
D20: Heading 1 | E20: BT
D21: Heading 2 | E21: BT
D22: Heading 3 | E22: BT
B24: Income Statement Inputs and Assumptions
C25: Revenue
D26: ='3-Statement'!D11 -> Revenue | I26: ='3-Statement'!I11 -> 20845 | J26: ='3-Statement'!J11 -> 20669 | K26: ='3-Statement'!K11 -> 20835 | L26: ='3-Statement'!L11 -> 20370 | M26: ='3-Statement'!M11 -> 19646 | N26: =M26*(1+N27) -> 19319.684 | O26: =N26*(1+O27) -> 19416.283 | P26: =O26*(1+P27) -> 19688.111 | Q26: =P26*(1+Q27) -> 19963.744 | R26: =Q26*(1+R27) -> 20243.237
D27: Growth Rate | J27: =(J26-I26)/I26 -> -0.0084432718 | K27: =(K26-J26)/J26 -> 0.0080313513 | L27: =(L26-K26)/K26 -> -0.022318215 | M27: =(M26-L26)/L26 -> -0.035542464 | N27: -0.016609776 | O27: 0.005 | P27: 0.014 | Q27: 0.014 | R27: 0.014
D28: Revenue contracting " mainly driven by lower International revenue including the impact of divesting entities in the year" - Q2 earnings report
D29: Due to the structural changes, I assume that the contraction will continue and eventually BT.L will grow again in line with the economy based on the expected benefits from their transformation and the growth in the sale of FTTP service. This is also in line with their guidance
D30: Growth is expected from FY2028 as per BT.L's earnings report guidance
D32: UK GDP Growth rate Q2 Y-o-Y | F32: 0.014 | L32: 0.01 | M32: 0.014 | N32: =$F$32 -> 0.014 | O32: =$F$32 -> 0.014 | P32: =$F$32 -> 0.014 | Q32: =$F$32 -> 0.014 | R32: =$F$32 -> 0.014
D33: United Kingdom GDP Annual Growth Rate
D34: My economic growth rate is based on "Trading Economics" data. I assume the UK's economy will grow based on the average of the last two y-o-y growth rates
C37: Cost of Sales
D38: ='3-Statement'!D12 -> Cost of Sales | E38: =money -> [£'M] | I38: =-'3-Statement'!I12 -> 7951 | J38: =-'3-Statement'!J12 -> 7820 | K38: =-'3-Statement'!K12 -> 7658 | L38: =-'3-Statement'!L12 -> 6777 | M38: =-'3-Statement'!M12 -> 6474 | N38: =N26*(1-N41) -> 6305.082 | O38: =O26*(1-O41) -> 6274.6218 | P38: =P26*(1-P41) -> 6299.3152 | Q38: =Q26*(1-Q41) -> 6323.1667 | R38: =R26*(1-R41) -> 6346.1423
D39: Growth rate | E39: % | J39: =(J38-I38)/I38 -> -0.016475915 | K39: =(K38-J38)/J38 -> -0.020716113 | L39: =(L38-K38)/K38 -> -0.11504309 | M39: =(M38-L38)/L38 -> -0.044710049
D40: ='3-Statement'!D13 -> Gross Profit | E40: =money -> [£'M] | I40: ='3-Statement'!I13 -> 12894 | J40: ='3-Statement'!J13 -> 12849 | K40: ='3-Statement'!K13 -> 13177 | L40: ='3-Statement'!L13 -> 13593 | M40: ='3-Statement'!M13 -> 13172
D41: Gross Profit Margin | E41: =money -> [£'M] | I41: =I40/I26 -> 0.6185656 | J41: =J40/J26 -> 0.62165562 | K41: =K40/K26 -> 0.6324454 | L41: =L40/L26 -> 0.66730486 | M41: =M40/M26 -> 0.67046727 | N41: =M41*(1+N42) -> 0.67364467 | O41: =N41*(1+O42) -> 0.67683712 | P41: =O41*(1+P42) -> 0.68004471 | Q41: =P41*(1+Q42) -> 0.68326749 | R41: =Q41*(1+R42) -> 0.68650555
D42: Growth rate | E42: % | J42: =J41/I41-1 -> 0.0049954544 | K42: =K41/J41-1 -> 0.017356531 | L42: =L41/K41-1 -> 0.055118522 | M42: =M41/L41-1 -> 0.0047390792 | N42: =M42 -> 0.0047390792 | O42: =N42 -> 0.0047390792 | P42: =O42 -> 0.0047390792 | Q42: =P42 -> 0.0047390792 | R42: =Q42 -> 0.0047390792
D44: BT.L is currently undergoing a cost cutting and cost efficiency program.
D45: I can assume that the benefits of this initiative would be reflected in the forecast period before it normalizes, hence I can forecasst a modest continued growth in gross profit margin.
C46: SG&A
D47: ='3-Statement'!D16 -> SGA | I47: =-'3-Statement'!I16 -> 5777 | J47: =-'3-Statement'!J16 -> 5496 | K47: =-'3-Statement'!K16 -> 6353 | L47: =-'3-Statement'!L16 -> 6482 | M47: =-'3-Statement'!M16 -> 5808 | N47: =N48*N26 -> 5648.3478 | O47: =O48*O26 -> 5735.6987 | P47: =P48*P26 -> 5932.1629 | Q47: =Q48*Q26 -> 6000.7884 | R47: =R48*R26 -> 6013.4269
D48: SG&A to Revenue (%) | I48: =I47/I26 -> 0.2771408 | J48: =J47/J26 -> 0.26590546 | K48: =K47/K26 -> 0.30491961 | L48: =L47/L26 -> 0.31821306 | M48: =M47/M26 -> 0.2956327 | N48: =AVERAGE(I48:M48) -> 0.29236233 | O48: =AVERAGE(J48:N48) -> 0.29540663 | P48: =AVERAGE(K48:O48) -> 0.30130686 | Q48: =AVERAGE(L48:P48) -> 0.30058432 | R48: =AVERAGE(M48:Q48) -> 0.29705857
...

Sheet DDM
B2: =company_name -> BT GROUP PLC
C3: Dividend Discount Model
C5: ="Balance Sheet Check: "&IF(bs_check=0,"Balanced as all things should be","Error!!!") -> Balance Sheet Check: Balanced as all things should be
D6: Description | E6: Units | F6: Inputs | I6: Hist | J6: Hist | K6: Hist | L6: Hist | M6: Hist | N6: Forecast | O6: Forecast | P6: Forecast | Q6: Forecast | R6: Forecast | S6: Term
I7: 2022 | J7: 2023 | K7: 2024 | L7: 2025 | M7: =base_year -> 2026 | N7: =M7+1 -> 2027 | O7: =N7+1 -> 2028 | P7: =O7+1 -> 2029 | Q7: =P7+1 -> 2030 | R7: =Q7+1 -> 2031
C10: Perpetual Growth Rate (G)
D11: Net Profit Margin | F11: ='3-Statement'!M36/'3-Statement'!M11 -> 0.05482032
D12: Asset Turnover | F12: ='3-Statement'!M11/'Hist - BS'!E250 -> 0.39310869
D13: Financial Leverage | F13: ='3-Statement'!M70/'3-Statement'!M101 -> 3.9777141
D14: Return on Equity 2026 | E14: % | F14: =F11*F12*F13 -> 0.085721108
D15: Payout Ratio | E15: % | F15: =Inputs!M52 -> 0.7632312
D16: Retention Rate | E16: % | F16: =1-F15 -> 0.2367688
D17: Growth Rate | E17: % | F17: =F14*F16 -> 0.020296084
D18: Notice: Growth Rate is greater than the growth rate of the economy
D19: I used Gordon Growth Model because the company is a mature company and grows slower and around the same rate as it's host country's (UK) economy
D21: Cost of Equity | E21: % | F21: ='Investment recommendation'!Q57 -> 0.092604508
D22: Growth Rate | E22: % | F22: ='Investment recommendation'!Q58 -> 0.020296084
D24: Dividends | E24: [£'M] | I24: =Inputs!I51 -> 755 | J24: =Inputs!J51 -> 760 | K24: =Inputs!K51 -> 783 | L24: =Inputs!L51 -> 801 | M24: =Inputs!M51 -> 822 | N24: =Inputs!N51 -> 854.18687 | O24: =Inputs!O51 -> 879.81247 | P24: =Inputs!P51 -> 906.20685 | ... R24: =Inputs!R51 -> 961.39484 | S24: =R24*(1+F22) -> 980.90739
D25: Payout Ratio | E25: % | I25: =Inputs!I52 -> 0.59262166 | J25: =Inputs!J52 -> 0.39895013 | K25: =Inputs!K52 -> 0.91578947 | L25: =Inputs!L52 -> 0.75996205 | M25: =Inputs!M52 -> 0.7632312 | N25: =Inputs!N52 -> 0.5426898 | O25: =Inputs!O52 -> 0.489139 | P25: =Inputs!P52 -> 0.46018345 | ... S25: =Inputs!S52 -> 0
N27: =N7 -> 2027 | O27: =O7 -> 2028 | P27: =P7 -> 2029 | Q27: =Q7 -> 2030 | R27: =R7 -> 2031
D28: Dividends | E28: [£'M] | N28: =N24 -> 854.18687 | O28: =O24 -> 879.81247 | P28: =P24 -> 906.20685 | Q28: =Q24 -> 933.39305 | R28: =R24 -> 961.39484
D29: Terminal Value | E29: [£'M] | R29: =S24/(F21-F22) -> 13565.603
D30: Total Dividend | E30: [£'M] | N30: =SUM(N28:N29) -> 854.18687 | O30: =SUM(O28:O29) -> 879.81247 | P30: =SUM(P28:P29) -> 906.20685 | Q30: =SUM(Q28:Q29) -> 933.39305 | R30: =SUM(R28:R29) -> 14526.998
M32: Valuation | N32: Discrete Period
M33: (YYYY-MM-DD) | N33: (YYYY-MM-DD) | O33: (YYYY-MM-DD) | P33: (YYYY-MM-DD) | Q33: (YYYY-MM-DD) | R33: (YYYY-MM-DD)
M34: 46308 | N34: 46477 | O34: =EDATE(N34,12) -> 46843 | P34: =EDATE(O34,12) -> 47208 | Q34: =EDATE(P34,12) -> 47573 | R34: =EDATE(Q34,12) -> 47938
D36: Discounting Period | M36: 0 | N36: =M36+YEARFRAC(M34,N34) -> 0.46666667 | O36: =N36+YEARFRAC(N34,O34) -> 1.4666667 | P36: =O36+YEARFRAC(O34,P34) -> 2.4666667 | Q36: =P36+YEARFRAC(P34,Q34) -> 3.4666667 | R36: =Q36+YEARFRAC(Q34,R34) -> 4.4666667
D37: Present Value of Dividends | E37: [£'M] | N37: =N30/(1+$F$21)^N36 -> 819.60292 | O37: =O30/(1+$F$21)^O36 -> 772.64097 | P37: =P30/(1+$F$21)^P36 -> 728.36986 | Q37: =Q30/(1+$F$21)^Q36 -> 686.63542 | R37: =R30/(1+$F$21)^R36 -> 9780.8036
C39: Dividend Discount Model
D40: Intrinsic Equity Value | E40: [£'M] | F40: =SUM(N37:R37) -> 12788.053
D41: Shares Outstanding | E41: Units in M | F41: =Inputs!F59/1000000 -> 9967.6399
D42: Valuation Date | E42: Date | F42: =M34 -> 46308
D43: Intrinsic Equity Value per share | E43: Pence/sh | F43: =F40/F41*100 -> 128.29569
D44: Current Share Price | E44: Pence/sh | F44: =Inputs!F60 -> 209.7
D45: Judgement | E45: Text | F45: =IF(F44<F43, "Undervalued", "Overvalued") -> Overvalued

Sheet FCFF
B2: =company_name -> BT GROUP PLC
C3: FCFF/FCFE Model
C5: ="Balance Sheet Check: "&IF(bs_check=0,"Balanced as all things should be","Error!!!") -> Balance Sheet Check: Balanced as all things should be
D6: Description | E6: Units | F6: Inputs | I6: Hist | J6: Hist | K6: Hist | L6: Hist | M6: Hist | N6: Forecast | O6: Forecast | P6: Forecast | Q6: Forecast | R6: Forecast | S6: Term
I7: 2022 | J7: 2023 | K7: 2024 | L7: 2025 | M7: =base_year -> 2026 | N7: =M7+1 -> 2027 | O7: =N7+1 -> 2028 | P7: =O7+1 -> 2029 | Q7: =P7+1 -> 2030 | R7: =Q7+1 -> 2031
D9: =Inputs!D67 -> Uk Corporate Tax Rate | E9: =Inputs!E67 -> % | F9: =Inputs!F67 -> 0.25
D10: WACC | E10: % | F10: ='Investment recommendation'!Q56 -> 0.068424935
D11: =Inputs!D32 -> UK GDP Growth rate Q2 Y-o-Y | E11: % | F11: ='Investment recommendation'!Q59 -> 0.014
D12: =Inputs!D59 -> Shares Outstanding | E12: =Inputs!E59 -> Unit | F12: =Inputs!F59 -> 9967639866
B14: Unlevered Free Cashflow to the Firm
D15: ='3-Statement'!D21 -> EBIT | N15: ='3-Statement'!N21 -> 2586.1652 | O15: ='3-Statement'!O21 -> 2879.9705 | P15: ='3-Statement'!P21 -> 3086.0731 | Q15: ='3-Statement'!Q21 -> 3460.7102 | R15: ='3-Statement'!R21 -> 3867.9587 | S15: =R15*(1+$F$11) -> 3922.1101
D16: Unlevered Taxes | N16: =-N15*$F$9 -> -646.5413 | O16: =-O15*$F$9 -> -719.99264 | P16: =-P15*$F$9 -> -771.51829 | Q16: =-Q15*$F$9 -> -865.17756 | R16: =-R15*$F$9 -> -966.98968 | S16: =R16*(1+$F$11) -> -980.52753
D18: Net Operating profit After Tax (NOPAT) | N18: =SUM(N15:N16) -> 1939.6239 | O18: =SUM(O15:O16) -> 2159.9779 | P18: =SUM(P15:P16) -> 2314.5549 | Q18: =SUM(Q15:Q16) -> 2595.5327 | R18: =SUM(R15:R16) -> 2900.969 | S18: =R18*(1+$F$11) -> 2941.5826
D19: ='3-Statement'!D111 -> Depreciation & Amortization | N19: ='3-Statement'!N111 -> 4780.0893 | O19: ='3-Statement'!O111 -> 4525.9918 | P19: ='3-Statement'!P111 -> 4370.5595 | Q19: ='3-Statement'!Q111 -> 4179.0789 | R19: ='3-Statement'!R111 -> 4015.7088 | S19: =R19*(1+$F$11) -> 4071.9287
D20: ='3-Statement'!D114 -> Change in UFCF OWC | N20: ='3-Statement'!N194 -> 194.05619 | O20: ='3-Statement'!O194 -> 57.35645 | P20: ='3-Statement'!P194 -> 58.02685 | Q20: ='3-Statement'!Q194 -> 101.67065 | R20: ='3-Statement'!R194 -> 116.79868 | S20: =R20*(1+$F$11) -> 118.43387
D21: ='3-Statement'!D122 -> Investing Cashflows | N21: ='3-Statement'!N122 -> -4958.7828 | O21: ='3-Statement'!O122 -> -4757.1148 | P21: ='3-Statement'!P122 -> -4563.6485 | Q21: ='3-Statement'!Q122 -> -4378.0502 | R21: ='3-Statement'!R122 -> -4200 | S21: =R21*(1+$F$11) -> -4258.8
D22: FCFF | N22: =SUM(N18:N21) -> 1954.9866 | O22: =SUM(O18:O21) -> 1986.2113 | P22: =SUM(P18:P21) -> 2179.4927 | Q22: =SUM(Q18:Q21) -> 2498.232 | R22: =SUM(R18:R21) -> 2833.4765 | S22: =SUM(S18:S21) -> 2873.1452
M26: Valuation | N26: Discrete Period
M27: (YYYY-MM-DD) | N27: (YYYY-MM-DD) | O27: (YYYY-MM-DD) | P27: (YYYY-MM-DD) | Q27: (YYYY-MM-DD) | R27: (YYYY-MM-DD)
M28: 46308 | N28: 46477 | O28: =EDATE(N28,12) -> 46843 | P28: =EDATE(O28,12) -> 47208 | Q28: =EDATE(P28,12) -> 47573 | R28: =EDATE(Q28,12) -> 47938
D29: FCFF | N29: =N22 -> 1954.9866 | O29: =O22 -> 1986.2113 | P29: =P22 -> 2179.4927 | Q29: =Q22 -> 2498.232 | R29: =R22 -> 2833.4765
D30: Terminal value | R30: =S22/(F10-F11) -> 52790.972
D31: Total Cashflow | N31: =SUM(N29:N30) -> 1954.9866 | O31: =SUM(O29:O30) -> 1986.2113 | P31: =SUM(P29:P30) -> 2179.4927 | Q31: =SUM(Q29:Q30) -> 2498.232 | R31: =SUM(R29:R30) -> 55624.449
C34: Discounted FCFF
D35: Years for Discounting | M35: 0 | N35: =M35+YEARFRAC(M28,N28) -> 0.46666667 | O35: =N35+YEARFRAC(N28,O28) -> 1.4666667 | P35: =O35+YEARFRAC(O28,P28) -> 2.4666667 | Q35: =P35+YEARFRAC(P28,Q28) -> 3.4666667 | R35: =Q35+YEARFRAC(Q28,R28) -> 4.4666667
D37: Discrete Forecaast | M37: 0 | N37: =N29/(1+$F$10)^N35 -> 1895.5268 | O37: =O29/(1+$F$10)^O35 -> 1802.468 | P37: =P29/(1+$F$10)^P35 -> 1851.2007 | Q37: =Q29/(1+$F$10)^Q35 -> 1986.0348 | R37: =R29/(1+$F$10)^R35 -> 2108.2868
D38: Terminal Value | M38: 0 | R38: =R30/(1+F10)^R35 -> 39279.841
D39: Total FCFF | N39: =SUM(N37:N38) -> 1895.5268 | O39: =SUM(O37:O38) -> 1802.468 | P39: =SUM(P37:P38) -> 1851.2007 | Q39: =SUM(Q37:Q38) -> 1986.0348 | R39: =SUM(R37:R38) -> 41388.128
D41: FCFF/FCFE Model
D42: Enterprise Value | E42: =money -> [£'M] | F42: =SUM(N39:R39) -> 48923.358
D43: Less: MV Debt | E43: =money -> [£'M] | F43: =-'Cost of Capital'!F16/1000000 -> -17410.345
D44: Add: Cash and Cash Equivalents | E44: =money -> [£'M] | F44: ='3-Statement'!M50 -> 359
D45: Intrinsic Equity Value | E45: =money -> [£'M] | F45: =SUM(F42:F44) -> 31872.013
D46: Shares Outstanding | E46: Unit | F46: =F12/1000000 -> 9967.6399
D47: Current Share Price | E47: Pence/Sh | F47: =DDM!F44 -> 209.7
D48: Intrinsic Equity Value per Share | E48: Pence/Sh | F48: =F45/F46*100 -> 319.75487
D49: Judgement | E49: Text | F49: =IF(F48>F47, "Undervalued", "Overvalued") -> Undervalued
D51: This model may not account for the changes in the capital structure, so the WACC may be understated as the debt level of the company reduces.

Sheet RES.INC
B2: =company_name -> BT GROUP PLC
C3: Residual Income Model
C5: ="Balance Sheet Check: "&IF(bs_check=0,"Balanced as all things should be","Error!!!") -> Balance Sheet Check: Balanced as all things should be
D6: Description | E6: Units | F6: Inputs | I6: Hist | J6: Hist | K6: Hist | L6: Hist | M6: Hist | N6: Forecast | O6: Forecast | P6: Forecast | Q6: Forecast | R6: Forecast | S6: Term
I7: 2022 | J7: 2023 | K7: 2024 | L7: 2025 | M7: =base_year -> 2026 | N7: =M7+1 -> 2027 | O7: =N7+1 -> 2028 | P7: =O7+1 -> 2029 | Q7: =P7+1 -> 2030 | R7: =Q7+1 -> 2031
B8: Residual Income
D10: ='3-Statement'!D36 -> Net Income | E10: =money -> [£'M] | M10: ='3-Statement'!M36 -> 1077 | N10: ='3-Statement'!N36 -> 1573.9873 | O10: ='3-Statement'!O36 -> 1798.6962 | P10: ='3-Statement'!P36 -> 1969.2295 | Q10: ='3-Statement'!Q36 -> 2264.4339 | R10: ='3-Statement'!R36 -> 2593.643
D11: ='3-Statement'!D101 -> Total Equity | E11: =money -> [£'M] | M11: ='3-Statement'!M101 -> 12564 | N11: ='3-Statement'!N101 -> 13283.8 | O11: ='3-Statement'!O101 -> 14202.684 | P11: ='3-Statement'!P101 -> 15265.707 | Q11: ='3-Statement'!Q101 -> 16596.748 | R11: ='3-Statement'!R101 -> 18228.996
D12: Return On Equity | E12: % | M12: =M10/M11 -> 0.085721108 | N12: =N10/N11 -> 0.11848923 | O12: =O10/O11 -> 0.12664481 | P12: =P10/P11 -> 0.12899694 | Q12: =Q10/Q11 -> 0.13643841 | R12: =R10/R11 -> 0.14228118
D13: ='Cost of Equity'!D15 -> Cost of Equity | E13: % | F13: ='Investment recommendation'!Q57 -> 0.092604508
D14: =DDM!D17 -> Growth Rate | E14: % | F14: ='Investment recommendation'!Q58 -> 0.020296084
D15: =FCFF!D12 -> Shares Outstanding | E15: =FCFF!E12 -> Unit | F15: =FCFF!F12/1000000 -> 9967.6399
D16: Total Equity Reconciles with the data from Refinitiv's financial summary and the condition of accounting clean surplus is shown in the retained earnings schedule
C18: Clean Surplus Accounting
C20: ='3-Statement'!C254 -> Retained Earnings
D21: ='3-Statement'!D255 -> Beginning Balance | M21: ='3-Statement'!M255 -> 0 | N21: ='3-Statement'!N255 -> 9554 | O21: ='3-Statement'!O255 -> 10273.8 | P21: ='3-Statement'!P255 -> 11192.684 | Q21: ='3-Statement'!Q255 -> 12255.707 | R21: ='3-Statement'!R255 -> 13586.748
D22: ='3-Statement'!D256 -> Net Income | M22: ='3-Statement'!M256 -> 0 | N22: ='3-Statement'!N256 -> 1573.9873 | O22: ='3-Statement'!O256 -> 1798.6962 | P22: ='3-Statement'!P256 -> 1969.2295 | Q22: ='3-Statement'!Q256 -> 2264.4339 | R22: ='3-Statement'!R256 -> 2593.643
D23: ='3-Statement'!D257 -> Dividends | M23: ='3-Statement'!M257 -> 0 | N23: ='3-Statement'!N257 -> -854.18687 | O23: ='3-Statement'!O257 -> -879.81247 | P23: ='3-Statement'!P257 -> -906.20685 | Q23: ='3-Statement'!Q257 -> -933.39305 | R23: ='3-Statement'!R257 -> -961.39484
D24: ='3-Statement'!D258 -> Ending Balance | M24: ='3-Statement'!M258 -> 9554 | N24: ='3-Statement'!N258 -> 10273.8 | O24: ='3-Statement'!O258 -> 11192.684 | P24: ='3-Statement'!P258 -> 12255.707 | Q24: ='3-Statement'!Q258 -> 13586.748 | R24: ='3-Statement'!R258 -> 15218.996
C26: ='3-Statement'!C94 -> Equity
D27: ='3-Statement'!D95 -> Share capital | M27: ='3-Statement'!M95 -> 499 | N27: ='3-Statement'!N95 -> 499 | O27: ='3-Statement'!O95 -> 499 | P27: ='3-Statement'!P95 -> 499 | Q27: ='3-Statement'!Q95 -> 499 | R27: ='3-Statement'!R95 -> 499
D28: ='3-Statement'!D96 -> Share premium | M28: ='3-Statement'!M96 -> 1051 | N28: ='3-Statement'!N96 -> 1051 | O28: ='3-Statement'!O96 -> 1051 | P28: ='3-Statement'!P96 -> 1051 | Q28: ='3-Statement'!Q96 -> 1051 | R28: ='3-Statement'!R96 -> 1051
D29: ='3-Statement'!D97 -> Own shares | M29: ='3-Statement'!M97 -> -188 | N29: ='3-Statement'!N97 -> -188 | O29: ='3-Statement'!O97 -> -188 | P29: ='3-Statement'!P97 -> -188 | Q29: ='3-Statement'!Q97 -> -188 | R29: ='3-Statement'!R97 -> -188
D30: ='3-Statement'!D98 -> Merger reserve | M30: ='3-Statement'!M98 -> 998 | N30: ='3-Statement'!N98 -> 998 | O30: ='3-Statement'!O98 -> 998 | P30: ='3-Statement'!P98 -> 998 | Q30: ='3-Statement'!Q98 -> 998 | R30: ='3-Statement'!R98 -> 998
D31: ='3-Statement'!D99 -> Other reserves | M31: ='3-Statement'!M99 -> 650 | N31: ='3-Statement'!N99 -> 650 | O31: ='3-Statement'!O99 -> 650 | P31: ='3-Statement'!P99 -> 650 | Q31: ='3-Statement'!Q99 -> 650 | R31: ='3-Statement'!R99 -> 650
D32: ='3-Statement'!D100 -> Retained earnings | M32: ='3-Statement'!M100 -> 9554 | N32: ='3-Statement'!N100 -> 10273.8 | O32: ='3-Statement'!O100 -> 11192.684 | P32: ='3-Statement'!P100 -> 12255.707 | Q32: ='3-Statement'!Q100 -> 13586.748 | R32: ='3-Statement'!R100 -> 15218.996
D33: ='3-Statement'!D101 -> Total Equity | M33: ='3-Statement'!M101 -> 12564 | N33: ='3-Statement'!N101 -> 13283.8 | O33: ='3-Statement'!O101 -> 14202.684 | P33: ='3-Statement'!P101 -> 15265.707 | Q33: ='3-Statement'!Q101 -> 16596.748 | R33: ='3-Statement'!R101 -> 18228.996
C36: Model
D37: =D12 -> Return On Equity | E37: =E12 -> % | M37: =M12 -> 0.085721108 | N37: =N12 -> 0.11848923 | O37: =O12 -> 0.12664481 | P37: =P12 -> 0.12899694 | Q37: =Q12 -> 0.13643841 | R37: =R12 -> 0.14228118
D38: Cost of Equity | E38: =E13 -> % | M38: =$F$13 -> 0.092604508 | N38: =$F$13 -> 0.092604508 | O38: =$F$13 -> 0.092604508 | P38: =$F$13 -> 0.092604508 | Q38: =$F$13 -> 0.092604508 | R38: =$F$13 -> 0.092604508
D39: Required Rate of Return (Equity Charge) | E39: =money -> [£'M] | N39: =N38*M11 -> 1163.483 | O39: =O38*N11 -> 1230.1398 | P39: =P38*O11 -> 1315.2326 | Q39: =Q38*P11 -> 1413.6733 | R39: =R38*Q11 -> 1536.9337
D40: Residual Income | E40: =money -> [£'M] | N40: =N10-N39 -> 410.5043 | O40: =O10-O39 -> 568.55641 | P40: =P10-P39 -> 653.99697 | Q40: =Q10-Q39 -> 850.76067 | R40: =R10-R39 -> 1056.7093 | S40: =R40*(1+$F$14) -> 1078.1564
M44: Valuation | N44: Discrete Period | S44: Term
M45: (YYYY-MM-DD) | N45: (YYYY-MM-DD) | O45: (YYYY-MM-DD) | P45: (YYYY-MM-DD) | Q45: (YYYY-MM-DD) | R45: (YYYY-MM-DD) | S45: (YYYY-MM-DD)
M46: 46308 | N46: 46477 | O46: =EDATE(N46,12) -> 46843 | P46: =EDATE(O46,12) -> 47208 | Q46: =EDATE(P46,12) -> 47573 | R46: =EDATE(Q46,12) -> 47938 | S46: =EDATE(R46,12) -> 48304
D48: Discounting Period | M48: 0 | N48: =M48+YEARFRAC(M46,N46) -> 0.46666667 | O48: =N48+YEARFRAC(N46,O46) -> 1.4666667 | P48: =O48+YEARFRAC(O46,P46) -> 2.4666667 | Q48: =P48+YEARFRAC(P46,Q46) -> 3.4666667 | R48: =Q48+YEARFRAC(Q46,R46) -> 4.4666667
D50: =D40 -> Residual Income | N50: =N40 -> 410.5043 | O50: =O40 -> 568.55641 | P50: =P40 -> 653.99697 | Q50: =Q40 -> 850.76067 | R50: =R40 -> 1056.7093
D51: Terminal Value | R51: =S40/(F13-F14) -> 14910.522
D52: Total Cashflow | N52: =SUM(N50:N51) -> 410.5043 | O52: =SUM(O50:O51) -> 568.55641 | P52: =SUM(P50:P51) -> 653.99697 | Q52: =SUM(Q50:Q51) -> 850.76067 | R52: =SUM(R50:R51) -> 15967.232
D54: Present Value of Cashflows | N54: =N52/(1+$F$13)^N48 -> 393.88398 | O54: =O52/(1+$F$13)^O48 -> 499.29955 | P54: =P52/(1+$F$13)^P48 -> 525.65448 | Q54: =Q52/(1+$F$13)^Q48 -> 625.84826 | R54: =R52/(1+$F$13)^R48 -> 10750.49
...

Sheet COMPS
B2: =company_name -> BT GROUP PLC
C5: Market Data as at | D5: ='Cover Page'!F16 -> 46319
C6: Company Name | D6: EV / Revenue (NTM) | E6: EV / EBITDA | F6: Price / EPS (NTM) | G6: Price / Cash Flow Per Share (NTM) | H6: Price / Book Value Per Share (NTM) | I6: Price / Revenue (NTM) | J6: Dividend Per Share Yield % (NTM) | K6: Price / Free Cash Flow Per Share (FY1) | L6: Price / CAPEX (FY1) | M6: Return On Equity | N6: Net Debt to Total Equity (FY0) | O6: Asset Turnover (FY0) | P6: Quick Ratio (FY0) | Q6: Gross Profit Margin - % (FY0) | R6: Net Income Margin - Actual (FY0) | S6: Company Market Capitalization (usd)
C7: Vodafone Group PLC | D7: 1.6054114 | E7: 5.3145 | F7: 11.321447 | G7: 2.722113 | H7: 0.71142604 | I7: 0.71669884 | J7: 0.034609165 | K7: 15.878295 | L7: 4.0371381 | M7: 0.0943 | N7: 0.67845 | O7: 0.31311838 | P7: 1.10531 | Q7: 0.3146981 | R7: 0.07129 | S7: 3.6617543e+10
C8: Deutsche Telekom AG | D8: 2.2173078 | E8: 5.3203787 | F8: 9.8976226 | G8: 3.0425025 | H8: 1.8871344 | I8: 0.95215508 | J8: 0.050041882 | K8: 7.983025 | L8: 6.7501665 | M8: 0.0534 | N8: 1.44198 | O8: 0.40047217 | P8: 1.0397 | Q8: 0.4121396 | R8: 0.08189 | S8: 1.3771914e+11
C9: Koninklijke KPN NV | D9: 3.7062689 | E9: 7.7989013 | F9: 15.877067 | G9: 6.4689476 | H9: 4.1556963 | I9: 2.5792855 | J9: 0.059492002 | K9: 15.465058 | L9: 12.218014 | M9: 0.0003 | N9: 1.79641 | O9: 0.45937488 | P9: 0.61716 | Q9: 0.5632977 | R9: 0.14669 | S9: 1.739173e+10
C10: Swisscom AG | D10: 3.4156368 | E10: 7.5994206 | F10: 23.850831 | G10: 6.455936 | H10: 2.9618512 | I10: 2.4351628 | J10: 0.03958593 | K10: 25.129323 | L10: 9.9830601 | M10: -0.0356 | N10: 1.23517 | O10: 0.40742947 | P10: 0.73192 | Q10: 0.4723551 | R10: 0.08439 | S10: 4.2985125e+10
C11: Telefonica SA | D11: 1.7168172 | E11: 4.8618477 | F11: 8.6634731 | G11: 2.3107303 | H11: 1.3059154 | I11: 0.56821591 | J11: 0.045608536 | K11: 12.600407 | L11: 4.0459247 | M11: 0.0608 | N11: 1.83738 | O11: 0.36484711 | P11: 0.85127 | Q11: 0.2889237 | R11: 0.0604 | S11: 2.1703755e+10
C12: Telia Company AB (publ) | D12: 3.1351973 | E12: 7.9493401 | F12: 18.271108 | G12: 6.6569727 | H12: 3.669829 | I12: 2.209192 | J12: 0.046492328 | K12: 6.5415947 | L12: 14.195216 | M12: 0 | N12: 1.30212 | O12: 0.41157442 | P12: 0.87113 | Q12: 0.3533378 | R12: 0.09509 | S12: 1.9111146e+10
C13: Orange SA | D13: 1.7940852 | E13: 5.4176049 | F13: 12.28317 | G13: 2.8195077 | H13: 1.1636725 | I13: 0.78726541 | J13: 0.057849837 | K13: 10.049204 | L13: 5.0521087 | M13: 0.035 | N13: 0.91256 | O13: 0.38237674 | P13: 1.08547 | Q13: 0.5906525 | R13: 0.0608 | S13: 4.2327886e+10
C14: BT Group PLC | D14: 2.4086191 | E14: 5.2143384 | F14: 11.216754 | G14: 3.1268146 | H14: 1.5799143 | I14: 1.2086569 | J14: 0.040961824 | K14: 15.047327 | L14: 4.6607584 | M14: =DDM!F14 -> 0.085721108 | N14: 1.6716 | O14: 0.38919154 | P14: 0.80259 | Q14: 0.423445 | R14: 0.0913 | S14: 2.8230295e+10
C16: Maximum | D16: =MAX(D7:D13) -> 3.7062689 | E16: =MAX(E7:E13) -> 7.9493401 | F16: =MAX(F7:F13) -> 23.850831 | G16: =MAX(G7:G13) -> 6.6569727 | H16: =MAX(H7:H13) -> 4.1556963 | I16: =MAX(I7:I13) -> 2.5792855 | J16: =MAX(J7:J13) -> 0.059492002 | K16: 23.268548 | L16: 13.16136 | M16: =MAX(M7:M13) -> 0.0943 | N16: =MAX(N7:N13) -> 1.83738 | O16: =MAX(O7:O13) -> 0.45937488 | P16: =MAX(P7:P13) -> 1.10531 | Q16: =MAX(Q7:Q13) -> 0.5906525 | R16: =MAX(R7:R13) -> 0.14669 | S16: =MAX(S7:S13) -> 1.3771914e+11
C17: Average | D17: =AVERAGE(D7:D13) -> 2.5129606 | E17: =AVERAGE(E7:E13) -> 6.3231419 | F17: =AVERAGE(F7:F13) -> 14.309245 | G17: =AVERAGE(G7:G13) -> 4.3538157 | H17: =AVERAGE(H7:H13) -> 2.265075 | I17: =AVERAGE(I7:I13) -> 1.4639965 | J17: =AVERAGE(J7:J13) -> 0.047668526 | K17: 13.258452 | L17: 7.6634987 | M17: =AVERAGE(M7:M13) -> 0.029742857 | N17: =AVERAGE(N7:N13) -> 1.3148671 | O17: =AVERAGE(O7:O13) -> 0.39131331 | P17: =AVERAGE(P7:P13) -> 0.90028 | Q17: =AVERAGE(Q7:Q13) -> 0.42791493 | R17: =AVERAGE(R7:R13) -> 0.085792857 | S17: =AVERAGE(S7:S13) -> 4.5408046e+10
C18: Median | D18: =MEDIAN(D7:D13) -> 2.2173078 | E18: =MEDIAN(E7:E13) -> 5.4176049 | F18: =MEDIAN(F7:F13) -> 12.28317 | G18: =MEDIAN(G7:G13) -> 3.0425025 | H18: =MEDIAN(H7:H13) -> 1.8871344 | I18: =MEDIAN(I7:I13) -> 0.95215508 | J18: =MEDIAN(J7:J13) -> 0.046492328 | K18: 11.884447 | L18: 6.7325942 | M18: =MEDIAN(M7:M13) -> 0.035 | N18: =MEDIAN(N7:N13) -> 1.30212 | O18: =MEDIAN(O7:O13) -> 0.40047217 | P18: =MEDIAN(P7:P13) -> 0.87113 | Q18: =MEDIAN(Q7:Q13) -> 0.4121396 | R18: =MEDIAN(R7:R13) -> 0.08189 | S18: =MEDIAN(S7:S13) -> 3.6617543e+10
C19: Minimum | D19: =MIN(D7:D13) -> 1.6054114 | E19: =MIN(E7:E13) -> 4.8618477 | F19: =MIN(F7:F13) -> 8.6634731 | G19: =MIN(G7:G13) -> 2.3107303 | H19: =MIN(H7:H13) -> 0.71142604 | I19: =MIN(I7:I13) -> 0.56821591 | J19: =MIN(J7:J13) -> 0.034609165 | K19: 7.9581285 | L19: 3.81193 | M19: =MIN(M7:M13) -> -0.0356 | N19: =MIN(N7:N13) -> 0.67845 | O19: =MIN(O7:O13) -> 0.31311838 | P19: =MIN(P7:P13) -> 0.61716 | Q19: =MIN(Q7:Q13) -> 0.2889237 | R19: =MIN(R7:R13) -> 0.0604 | S19: =MIN(S7:S13) -> 1.739173e+10
C23: BT Group PLC | D23: =D14 -> 2.4086191 | E23: =E14 -> 5.2143384 | F23: =F14 -> 11.216754 | G23: =G14 -> 3.1268146 | H23: =H14 -> 1.5799143 | I23: =I14 -> 1.2086569 | J23: =J14 -> 0.040961824 | K23: =K14 -> 15.047327 | ... S23: =S14 -> 2.8230295e+10
C25: Relative Multiples | M25: Ranks vs Industry Peers
C26: Conclusion (Average) | D26: =IF(D$23>D17,"Overvalued", "Undervalued") -> Undervalued | E26: =IF(E$23>E17,"Overvalued", "Undervalued") -> Undervalued | F26: =IF(F$23>F17,"Overvalued", "Undervalued") -> Undervalued | G26: =IF(G$23>G17,"Overvalued", "Undervalued") -> Undervalued | H26: =IF(H$23>H17,"Overvalued", "Undervalued") -> Undervalued | I26: =IF(I$23>I17,"Overvalued", "Undervalued") -> Undervalued | J26: =IF(J$23>J17,"Overvalued", "Undervalued") -> Undervalued | K26: =IF(K$23>K17,"Overvalued", "Undervalued") -> Overvalued | L26: =IF(L$23>L17,"Overvalued", "Undervalued") -> Undervalued | M26: =_xlfn.RANK.AVG(M14,M7:M14) -> 2 | N26: =_xlfn.RANK.AVG(N14,N7:N14) -> 3 | O26: =_xlfn.RANK.AVG(O14,O7:O14) -> 5 | P26: =_xlfn.RANK.AVG(P14,P7:P14) -> 6 | Q26: =_xlfn.RANK.AVG(Q14,Q7:Q14) -> 4 | R26: =_xlfn.RANK.AVG(R14,R7:R14) -> 3 | S26: =_xlfn.RANK.AVG(S14,S7:S14) -> 5
C27: Conclusion (Median) | D27: =IF(D$23>D18,"Overvalued", "Undervalued") -> Overvalued | E27: =IF(E$23>E18,"Overvalued", "Undervalued") -> Undervalued | F27: =IF(F$23>F18,"Overvalued", "Undervalued") -> Undervalued | G27: =IF(G$23>G18,"Overvalued", "Undervalued") -> Overvalued | H27: =IF(H$23>H18,"Overvalued", "Undervalued") -> Undervalued | I27: =IF(I$23>I18,"Overvalued", "Undervalued") -> Overvalued | J27: =IF(J$23>J18,"Overvalued", "Undervalued") -> Undervalued | K27: =IF(K$23>K18,"Overvalued", "Undervalued") -> Overvalued | L27: =IF(L$23>L18,"Overvalued", "Undervalued") -> Undervalued
C30: Metric | D30: Rank | G30: Comparables Valuation
C31: Return On Equity | D31: {=TRANSPOSE(M26:S26)} -> 2 | G31: 2027F Earnings | H31: =money -> [£'M] | I31: ='3-Statement'!N36 -> 1573.9873
C32: Net Debt to Total Equity | D32: 3 | G32: Shares Outstanding | H32: Unit | I32: =Inputs!F59/1000000 -> 9967.6399
C33: Asset Turnover | D33: 5 | G33: Average P/E | H33: x | I33: =F17 -> 14.309245
C34: Quick Ratio | D34: 6 | G34: Forward EPS | H34: =money -> [£'M] | I34: =I31/I32 -> 0.15790973
C35: Gross Profit Margin | D35: 4 | G35: Potential Share Price | H35: Pence/sh | I35: =I33*I34*100 -> 225.95691
C36: Net Income Margin | D36: 3 | G36: Current Share Price | H36: Pence/sh | I36: ='RES.INC'!F63 -> 209.7
C37: Company Market Capitalization | D37: 5 | G37: Judgement | H37: Text | I37: =IF(I36<I35, "Undervalued", "Overvalued") -> Undervalued

Sheet Cost of Equity
B2: =company_name -> BT GROUP PLC
C3: Cost of Equity
C5: ="Balance Sheet Check: "&IF(bs_check=0,"Balanced as all things should be","Error!!!") -> Balance Sheet Check: Balanced as all things should be
C8: Cost of Equity
D9: Cost of Equity using the Capital Asset Pricing Model (CAPM)
D10: Variables | E10: Values
D11: Risk Free Rate | E11: =Inputs!F61 -> 0.0537
D12: Beta | E12: =_xlfn.COVARIANCE.S(G20:G86,H20:H86)/_xlfn.VAR.S(H20:H86) -> 1.0371912
D13: Expected Market Return | E13: =(1+MEDIAN(H20:H86))^4-1 -> 0.091209485
D14: Equity Risk Premium | E14: =E13-E11 -> 0.037509485
D15: Cost of Equity | E15: =E11+E12*E14 -> 0.092604508
C17: Data from Refinitv Workspace
D19: Exchange Date | E19: Close | F19: Net | G19: BT.L | H19: R_FTSE100 | I19: Risk - Free Rate | J19: Equity Risk Premium
D20: 46295 | E20: 192 | F20: 1.9 | G20: 0.0099947396 | H20: 0.010372369 | I20: =_xlfn.XLOOKUP(C21,'FRED YTM'!$B$2:$B$802,'FRED YTM'!$C$2:$C$802)/(4*100) -> 0.01248425 | J20: =H20-I20 -> -0.0021118812
C21: 09/2026 | D21: 46203 | E21: 190.1 | F21: -20.4 | G21: -0.096912114 | H21: 0.031510989 | I21: =_xlfn.XLOOKUP(C22,'FRED YTM'!$B$2:$B$802,'FRED YTM'!$C$2:$C$802)/(4*100) -> 0.01199 | J21: =H21-I21 -> 0.019520989
C22: 06/2026 | D22: 46112 | E22: 210.5 | F22: 26.45 | G22: 0.14371095 | H22: 0.024676329 | I22: =_xlfn.XLOOKUP(C23,'FRED YTM'!$B$2:$B$802,'FRED YTM'!$C$2:$C$802)/(4*100) -> 0.01175175 | J22: =H22-I22 -> 0.012924579
C23: 03/2026 | D23: 46022 | E23: 184.05 | F23: -7.1 | G23: -0.037143604 | H23: 0.062130832 | I23: =_xlfn.XLOOKUP(C24,'FRED YTM'!$B$2:$B$802,'FRED YTM'!$C$2:$C$802)/(4*100) -> 0.0112065 | J23: =H23-I23 -> 0.050924332
C24: 12/2025 | D24: 45930 | E24: 191.15 | F24: -2.6 | G24: -0.013419355 | H24: 0.067283722 | I24: =_xlfn.XLOOKUP(C25,'FRED YTM'!$B$2:$B$802,'FRED YTM'!$C$2:$C$802)/(4*100) -> 0.01172125 | J24: =H24-I24 -> 0.055562472
C25: 09/2025 | D25: 45838 | E25: 193.75 | F25: 27.9 | G25: 0.1682243 | H25: 0.020756605 | I25: =_xlfn.XLOOKUP(C26,'FRED YTM'!$B$2:$B$802,'FRED YTM'!$C$2:$C$802)/(4*100) -> 0.011312 | J25: =H25-I25 -> 0.0094446054
C26: 06/2025 | D26: 45747 | E26: 165.85 | F26: 21.8 | G26: 0.15133634 | H26: 0.050139361 | I26: =_xlfn.XLOOKUP(C27,'FRED YTM'!$B$2:$B$802,'FRED YTM'!$C$2:$C$802)/(4*100) -> 0.011612 | J26: =H26-I26 -> 0.038527361
C27: 03/2025 | D27: 45657 | E27: 144.05 | F27: -3.85 | G27: -0.026031102 | H27: -0.007761368 | I27: =_xlfn.XLOOKUP(C28,'FRED YTM'!$B$2:$B$802,'FRED YTM'!$C$2:$C$802)/(4*100) -> 0.01108625 | J27: =H27-I27 -> -0.018847618
C28: 12/2024 | D28: 45565 | E28: 147.9 | F28: 7.55 | G28: 0.053794086 | H28: 0.008920741 | I28: =_xlfn.XLOOKUP(C29,'FRED YTM'!$B$2:$B$802,'FRED YTM'!$C$2:$C$802)/(4*100) -> 0.00976325 | J28: =H28-I28 -> -0.000842509
C29: 09/2024 | D29: 45473 | E29: 140.35 | F29: 30.7 | G29: 0.27998176 | H29: 0.026595009 | I29: =_xlfn.XLOOKUP(C30,'FRED YTM'!$B$2:$B$802,'FRED YTM'!$C$2:$C$802)/(4*100) -> 0.010411 | J29: =H29-I29 -> 0.016184009
C30: 06/2024 | D30: 45382 | E30: 109.65 | F30: -13.95 | G30: -0.11286408 | H30: 0.028368446 | I30: =_xlfn.XLOOKUP(C31,'FRED YTM'!$B$2:$B$802,'FRED YTM'!$C$2:$C$802)/(4*100) -> 0.0100825 | J30: =H30-I30 -> 0.018285946
C31: 03/2024 | D31: 45291 | E31: 123.6 | F31: 6.9 | G31: 0.059125964 | H31: 0.016450931 | I31: =_xlfn.XLOOKUP(C32,'FRED YTM'!$B$2:$B$802,'FRED YTM'!$C$2:$C$802)/(4*100) -> 0.0096555 | J31: =H31-I31 -> 0.0067954311
C32: 12/2023 | D32: 45199 | E32: 116.7 | F32: -5.65 | G32: -0.046178995 | H32: 0.010163937 | I32: =_xlfn.XLOOKUP(C33,'FRED YTM'!$B$2:$B$802,'FRED YTM'!$C$2:$C$802)/(4*100) -> 0.01104975 | J32: =H32-I32 -> -0.00088581253
... C39: 03/2022 | D39: 44561 | E39: 169.55 | F39: 9.75 | G39: 0.061013767 | H39: 0.042069197 | I39: =_xlfn.XLOOKUP(C40,'FRED YTM'!$B$2:$B$802,'FRED YTM'!$C$2:$C$802)/(4*100) -> 0.00209375 | J39: =H39-I39 -> 0.039975447
C40: 12/2021 | D40: 44469 | E40: 159.8 | F40: -34.2 | G40: -0.17628866 | H40: 0.0069556247
C41: 09/2021 | D41: 44377 | E41: 194 | F41: 39.2 | G41: 0.25322997 | H41: 0.0482362
D42: 44286 | E42: 154.8 | F42: 22.55 | G42: 0.1705104 | H42: 0.039177961
D43: 44196 | E43: 132.25 | F43: 33.87 | G43: 0.34427729 | H43: 0.10133138
D44: 44104 | E44: 98.38 | F44: -15.67 | G44: -0.13739588 | H44: -0.049214392
D45: 44012 | E45: 114.05 | F45: -3.85 | G45: -0.032654792 | H45: 0.08776155
D46: 43921 | E46: 117.9 | F46: -74.54 | G46: -0.38734151 | H46: -0.24799402
D47: 43830 | E47: 192.44 | F47: 13.86 | G47: 0.077612275 | H47: 0.018119087
D48: 43738 | E48: 178.58 | F48: -17.88 | G48: -0.091010893 | H48: -0.0023459289
D49: 43646 | E49: 196.46 | F49: -26.49 | G49: -0.11881588 | H49: 0.020117623
D50: 43555 | E50: 222.95 | F50: -15.15 | G50: -0.063628727 | H50: 0.081903887
D51: 43465 | E51: 238.1 | F51: 12.8 | G51: 0.056813138 | H51: -0.10413438
D52: 43373 | E52: 225.3 | F52: 7.5 | G52: 0.034435262 | H52: -0.016594364
...

Sheet Cost of Capital
B2: =company_name -> BT GROUP PLC
C3: Cost of Capital
C5: ="Balance Sheet Check: "&IF(bs_check=0,"Balanced as all things should be","Error!!!") -> Balance Sheet Check: Balanced as all things should be
D7: =Inputs!D67 -> Uk Corporate Tax Rate | E7: =Inputs!E67 -> % | F7: =Inputs!F67 -> 0.25
D8: =Inputs!D59 -> Shares Outstanding | E8: =Inputs!E59 -> Unit | F8: =Inputs!F59 -> 9967639866
D9: =Inputs!D60 -> Current Share Price | E9: =Inputs!E60 -> Pence/Sh | F9: =Inputs!F60 -> 209.7
D10: BT Cost of Debt | F10: ='Debt Structure'!B53 -> 0.052527918
C13: Weighted Average Cost of Capital
D14: Capital Structure | F14: Values | G14: Weights | H14: Costs | I14: WACC
D15: Equity | F15: =F8*(F9/100) -> 2.0902141e+10 | G15: =F15/$F$17 -> 0.54556995 | H15: ='Cost of Equity'!E15 -> 0.092604508 | I15: =G15*H15 -> 0.050522236
D16: Market Value of Debt | F16: ='Debt Structure'!B52 -> 1.7410345e+10 | G16: =F16/$F$17 -> 0.45443005 | H16: =F10*(1-F7) -> 0.039395938 | I16: =G16*H16 -> 0.017902698
D17: Total | F17: =SUM(F14:F16) -> 3.8312486e+10 | G17: =SUM(G15:G16) -> 1 | I17: =SUM(I15:I16) -> 0.068424935

Sheet 3-Statement
B2: =company_name -> BT GROUP PLC
C3: 3 - Statement Model & Schedules
C5: ="Balance Sheet Check: "&IF(bs_check=0,"Balanced as all things should be","Error!!!") -> Balance Sheet Check: Balanced as all things should be
D6: Description | E6: Units | F6: Inputs | I6: Hist | J6: Hist | K6: Hist | L6: Hist | M6: Hist | N6: Forecast | O6: Forecast | P6: Forecast | Q6: Forecast | R6: Forecast | S6: Term
I7: 2022 | J7: 2023 | K7: 2024 | L7: 2025 | M7: =base_year -> 2026 | N7: =M7+1 -> 2027 | O7: =N7+1 -> 2028 | P7: =O7+1 -> 2029 | Q7: =P7+1 -> 2030 | R7: =Q7+1 -> 2031
B8: 3- Statements
C9: Income Statement
D11: ='Hist - IS'!C204 -> Revenue | I11: ='Hist - IS'!H204 -> 20845 | J11: ='Hist - IS'!G204 -> 20669 | K11: ='Hist - IS'!F204 -> 20835 | L11: ='Hist - IS'!E204 -> 20370 | M11: ='Hist - IS'!D204 -> 19646 | N11: =M11*(1+Inputs!N27) -> 19319.684 | O11: =N11*(1+Inputs!O27) -> 19416.283 | P11: =O11*(1+Inputs!P27) -> 19688.111 | Q11: =P11*(1+Inputs!Q27) -> 19963.744 | R11: =Q11*(1+Inputs!R27) -> 20243.237
D12: ='Hist - IS'!C207 -> Cost of Sales | I12: =-'Hist - IS'!H207 -> -7951 | J12: =-'Hist - IS'!G207 -> -7820 | K12: =-'Hist - IS'!F207 -> -7658 | L12: =-'Hist - IS'!E207 -> -6777 | M12: =-'Hist - IS'!D207 -> -6474 | N12: =-Inputs!N38 -> -6305.082 | O12: =-Inputs!O38 -> -6274.6218 | P12: =-Inputs!P38 -> -6299.3152 | Q12: =-Inputs!Q38 -> -6323.1667 | R12: =-Inputs!R38 -> -6346.1423
D13: Gross Profit | I13: =SUM(I11:I12) -> 12894 | J13: =SUM(J11:J12) -> 12849 | K13: =SUM(K11:K12) -> 13177 | L13: =SUM(L11:L12) -> 13593 | M13: =SUM(M11:M12) -> 13172 | N13: =SUM(N11:N12) -> 13014.602 | O13: =SUM(O11:O12) -> 13141.661 | P13: =SUM(P11:P12) -> 13388.796 | ... R13: =SUM(R11:R12) -> 13897.094
D14: Gross Profit Margin | I14: =I13/I$11 -> 0.6185656 | J14: =J13/J$11 -> 0.62165562 | K14: =K13/K$11 -> 0.6324454 | L14: =L13/L$11 -> 0.66730486 | M14: =M13/M$11 -> 0.67046727 | N14: =N13/N$11 -> 0.67364467 | O14: =O13/O$11 -> 0.67683712 | P14: =P13/P$11 -> 0.68004471 | ... R14: =R13/R$11 -> 0.68650555
D16: ='Hist - IS'!C217 -> SGA | I16: =-'Hist - IS'!H217 -> -5777 | J16: =-'Hist - IS'!G217 -> -5496 | K16: =-'Hist - IS'!F217 -> -6353 | L16: =-'Hist - IS'!E217 -> -6482 | M16: =-'Hist - IS'!D217 -> -5808 | N16: =-Inputs!N47 -> -5648.3478 | O16: =-Inputs!O47 -> -5735.6987 | P16: =-Inputs!P47 -> -5932.1629 | Q16: =-Inputs!Q47 -> -6000.7884 | R16: =-Inputs!R47 -> -6013.4269
D17: EBITDA | I17: =I13+I16 -> 7117 | J17: =J13+J16 -> 7353 | K17: =K13+K16 -> 6824 | L17: =L13+L16 -> 7111 | M17: =M13+M16 -> 7364 | N17: =N13+N16 -> 7366.2545 | O17: =O13+O16 -> 7405.9623 | P17: =P13+P16 -> 7456.6326 | ... R17: =R13+R16 -> 7883.6675
D18: EBITDA Margin | I18: =I17/I$11 -> 0.3414248 | J18: =J17/J$11 -> 0.35575016 | K18: =K17/K$11 -> 0.3275258 | L18: =L17/L$11 -> 0.3490918 | M18: =M17/M$11 -> 0.37483457 | N18: =N17/N$11 -> 0.38128234 | O18: =O17/O$11 -> 0.38143049 | P18: =P17/P$11 -> 0.37873784 | ... R18: =R17/R$11 -> 0.38944699
D20: ='Hist - IS'!C219 -> Depreciation & Amortization | I20: =-'Hist - IS'!H219 -> -4405 | J20: =-'Hist - IS'!G219 -> -4742 | K20: =-'Hist - IS'!F219 -> -4792 | L20: =-'Hist - IS'!E219 -> -4883 | M20: =-'Hist - IS'!D219 -> -4853 | N20: =-Inputs!N106 -> -4780.0893 | O20: =-Inputs!O106 -> -4525.9918 | P20: =-Inputs!P106 -> -4370.5595 | Q20: =-Inputs!Q106 -> -4179.0789 | R20: =-Inputs!R106 -> -4015.7088
D21: EBIT | I21: =I17+I20 -> 2712 | J21: =J17+J20 -> 2611 | K21: =K17+K20 -> 2032 | L21: =L17+L20 -> 2228 | M21: =M17+M20 -> 2511 | N21: =N17+N20 -> 2586.1652 | O21: =O17+O20 -> 2879.9705 | P21: =P17+P20 -> 3086.0731 | ... R21: =R17+R20 -> 3867.9587
D22: EBIT Margin | I22: =I21/I$11 -> 0.13010314 | J22: =J21/J$11 -> 0.12632445 | K22: =K21/K$11 -> 0.097528198 | L22: =L21/L$11 -> 0.10937653 | M22: =M21/M$11 -> 0.12781228 | N22: =N21/N$11 -> 0.13386167 | O22: =O21/O$11 -> 0.1483276 | P22: =P21/P$11 -> 0.15674806 | ... R22: =R21/R$11 -> 0.19107412
D24: ='Hist - IS'!C229 -> Interest Expense | I24: =-'Hist - IS'!H229 -> -761 | J24: =-'Hist - IS'!G229 -> -886 | K24: =-'Hist - IS'!F229 -> -1006 | L24: =-'Hist - IS'!E229 -> -1037 | M24: =-'Hist - IS'!D229 -> -963 | N24: =-N308+N310 -> -498.24722 | O24: =-O308+O310 -> -496.3373 | P24: =-P308+P310 -> -473.02778 | Q24: =-Q308+Q310 -> -452.13087 | R24: =-R308+R310 -> -421.83357
D25: ='Hist - IS'!C228 -> Interest Income | I25: ='Hist - IS'!H228 -> 12 | J25: ='Hist - IS'!G228 -> 63 | K25: ='Hist - IS'!F228 -> 181 | L25: ='Hist - IS'!E228 -> 151 | M25: ='Hist - IS'!D228 -> 98 | N25: =-N309 -> 10.731816 | O25: =-O309 -> 14.628362 | P25: =-P309 -> 12.594036 | Q25: =-Q309 -> 10.665909 | R25: =-R309 -> 12.065482
D26: Net Interest Expense | I26: =SUM(I24:I25) -> -749 | J26: =SUM(J24:J25) -> -823 | K26: =SUM(K24:K25) -> -825 | L26: =SUM(L24:L25) -> -886 | M26: =SUM(M24:M25) -> -865 | N26: =SUM(N24:N25) -> -487.5154 | O26: =SUM(O24:O25) -> -481.70894 | P26: =SUM(P24:P25) -> -460.43375 | ... R26: =SUM(R24:R25) -> -409.76809
D28: EBT | I28: =I21+I26 -> 1963 | J28: =J21+J26 -> 1788 | K28: =K21+K26 -> 1207 | L28: =L21+L26 -> 1342 | M28: =M21+M26 -> 1646 | N28: =N21+N26 -> 2098.6498 | O28: =O21+O26 -> 2398.2616 | P28: =P21+P26 -> 2625.6394 | ... R28: =R21+R26 -> 3458.1906
D30: Current Taxes | I30: =-'Hist - IS'!H235 -> 152 | J30: =-'Hist - IS'!G235 -> 5 | K30: =-'Hist - IS'!F235 -> -97 | L30: =-'Hist - IS'!E235 -> -84 | M30: =-'Hist - IS'!D235 -> -82 | N30: =-N275 -> -207.15409 | O30: =-O275 -> -282.05705 | P30: =-P275 -> -338.90149 | Q30: =-Q275 -> -437.30296 | R30: =-R275 -> -547.0393
D31: Deferred Taxes | I31: =-'Hist - IS'!H236 -> -841 | J31: =-'Hist - IS'!G236 -> 171 | K31: =-'Hist - IS'!F236 -> -234 | L31: =-'Hist - IS'!E236 -> -196 | M31: =-'Hist - IS'!D236 -> -277 | N31: =-N276 -> -317.50836 | O31: =-O276 -> -317.50836 | P31: =-P276 -> -317.50836 | Q31: =-Q276 -> -317.50836 | R31: =-R276 -> -317.50836
D32: Total Taxes | I32: =SUM(I30:I31) -> -689 | J32: =SUM(J30:J31) -> 176 | K32: =SUM(K30:K31) -> -331 | L32: =SUM(L30:L31) -> -280 | M32: =SUM(M30:M31) -> -359 | N32: =SUM(N30:N31) -> -524.66245 | O32: =SUM(O30:O31) -> -599.5654 | P32: =SUM(P30:P31) -> -656.40985 | ... R32: =SUM(R30:R31) -> -864.54765
D34: ='Hist - IS'!C239 -> Equity in Earnings/(Loss) of Affiliates (after Taxes) | I34: =-'Hist - IS'!H239 -> 0 | J34: =-'Hist - IS'!G239 -> -59 | K34: =-'Hist - IS'!F239 -> -21 | L34: =-'Hist - IS'!E239 -> -8 | M34: =-'Hist - IS'!D239 -> -210 | N34: =Inputs!N62 -> 0 | O34: =Inputs!O62 -> 0 | P34: =Inputs!P62 -> 0 | Q34: =Inputs!Q62 -> 0 | R34: =Inputs!R62 -> 0
D36: Net Income | I36: =I28+I32+I34 -> 1274 | J36: =J28+J32+J34 -> 1905 | K36: =K28+K32+K34 -> 855 | L36: =L28+L32+L34 -> 1054 | M36: =M28+M32+M34 -> 1077 | N36: =N28+N32+N34 -> 1573.9873 | O36: =O28+O32+O34 -> 1798.6962 | P36: =P28+P32+P34 -> 1969.2295 | ... R36: =R28+R32+R34 -> 2593.643
D39: EBITDA Margin | I39: =I17/I11 -> 0.3414248 | J39: =J17/J11 -> 0.35575016 | K39: =K17/K11 -> 0.3275258 | L39: =L17/L11 -> 0.3490918 | M39: =M17/M11 -> 0.37483457 | N39: =N17/N11 -> 0.38128234 | O39: =O17/O11 -> 0.38143049 | P39: =P17/P11 -> 0.37873784 | ... R39: =R17/R11 -> 0.38944699
D40: EBITDA Growth Rate | J40: =(J17-I17)/I17 -> 0.033160039 | K40: =(K17-J17)/J17 -> -0.071943424 | L40: =(L17-K17)/K17 -> 0.042057444 | M40: =(M17-L17)/L17 -> 0.035578681 | N40: =(N17-M17)/M17 -> 0.00030615269 | O40: =(O17-N17)/N17 -> 0.0053905016 | P40: =(P17-O17)/O17 -> 0.0068418258 | Q40: =(Q17-P17)/P17 -> 0.024562897 | R40: =(R17-Q17)/Q17 -> 0.031922138
D41: EBIT Margin | I41: =I21/I11 -> 0.13010314 | J41: =J21/J11 -> 0.12632445 | K41: =K21/K11 -> 0.097528198 | L41: =L21/L11 -> 0.10937653 | M41: =M21/M11 -> 0.12781228 | N41: =N21/N11 -> 0.13386167 | O41: =O21/O11 -> 0.1483276 | P41: =P21/P11 -> 0.15674806 | ... R41: =R21/R11 -> 0.19107412
D42: EBIT Growth Rate | J42: =J21/I21-1 -> -0.037241888 | K42: =K21/J21-1 -> -0.22175412 | L42: =L21/K21-1 -> 0.096456693 | M42: =M21/L21-1 -> 0.12701975 | N42: =N21/M21-1 -> 0.029934363 | O42: =O21/N21-1 -> 0.11360657 | P42: =P21/O21-1 -> 0.071564134 | Q42: =Q21/P21-1 -> 0.12139605 | R42: =R21/Q21-1 -> 0.11767772
D43: Net Income Margin | I43: =I36/I11 -> 0.061117774 | J43: =J36/J11 -> 0.092167013 | K43: =K36/K11 -> 0.041036717 | L43: =L36/L11 -> 0.051742759 | M43: =M36/M11 -> 0.05482032 | N43: =N36/N11 -> 0.081470655 | O43: =O36/O11 -> 0.092638546 | P43: =P36/P11 -> 0.10002126 | ... R43: =R36/R11 -> 0.12812393
D44: Net Income Growth Rate | J44: =J36/I36-1 -> 0.49529042 | K44: =K36/J36-1 -> -0.5511811 | L44: =L36/K36-1 -> 0.23274854 | M44: =M36/L36-1 -> 0.021821632 | N44: =N36/M36-1 -> 0.46145528 | O44: =O36/N36-1 -> 0.14276409 | P44: =P36/O36-1 -> 0.094809418 | Q44: =Q36/P36-1 -> 0.14990858 | R44: =R36/Q36-1 -> 0.14538248
C47: Balance Sheet
C49: Assets
D50: Cash & Cash Equivalents | L50: ='Hist - BS'!D248 -> 216 | M50: ='Hist - BS'!E248 -> 359 | N50: =N138 -> 1358.0905 | O50: =O138 -> 982.44736 | P50: =P138 -> 1032.5984 | Q50: =Q138 -> 673.94703 | R50: =R138 -> 1256.5301
D51: =Inputs!D85 -> Inventories | L51: ='Hist - BS'!D240 -> 331 | M51: ='Hist - BS'!E240 -> 366 | N51: =N156 -> 332.20058 | O51: =O156 -> 342.66204 | P51: =P156 -> 337.95365 | Q51: =Q156 -> 342.2732 | R51: =R156 -> 341.99138
D52: =Inputs!D86 -> Trade and other receivables | L52: ='Hist - BS'!D314 -> 3464 | M52: ='Hist - BS'!E314 -> 3549 | N52: =N157 -> 3387.7208 | O52: =O157 -> 3456.0808 | P52: =P157 -> 3478.3952 | Q52: =Q157 -> 3540.3106 | R52: =R157 -> 3583.1735
D53: =Inputs!D87 -> Preference shares in joint | L53: ='Hist - BS'!D242 -> 161 | M53: ='Hist - BS'!E242 -> 282 | N53: =N158 -> 282 | O53: =O158 -> 282 | P53: =P158 -> 282 | Q53: =Q158 -> 282 | R53: =R158 -> 282
D54: =Inputs!D88 -> Contract assets | L54: ='Hist - BS'!D243 -> 1194 | M54: ='Hist - BS'!E243 -> 1009 | N54: =N159 -> 982.67342 | O54: =O159 -> 977.92607 | P54: =P159 -> 981.77464 | Q54: =Q159 -> 985.49201 | R54: =R159 -> 989.07284
D55: =Inputs!D89 -> Assets classified as held | L55: ='Hist - BS'!D244 -> 245 | M55: ='Hist - BS'!E244 -> 0 | N55: =N160 -> 0 | O55: =O160 -> 0 | P55: =P160 -> 0 | Q55: =Q160 -> 0 | R55: =R160 -> 0
...

Sheet Debt Structure
A1: Debt Structure
A2: Name | C2: Issues | D2: Outstanding | E2: Issued
A3: Bonds | C3: 38 | D3: 1.8334841e+10 | E3: 1.8433185e+10
A4: Bonds to Be Issued | C4: 0 | D4: 0 | E4: 0
A5: Bonds (as Borrower) | C5: 0 | D5: 0 | E5: 0
A6: Bonds (as Borrower) - to Be Issued | C6: 0 | D6: 0 | E6: 0
A7: Loans | C7: 1 | D7: ="0" -> 0 | E7: 1.7825932e+09
A8: Total | C8: 39 | D8: 1.8334841e+10 | E8: 2.0215778e+10
A9: Inactive Bonds | C9: 273 | D9: ="0" -> 0 | E9: 4.8226041e+10
A13: Bonds
A14: Bonds
A15: Maturity | C15: Issues | D15: Outstanding (GBP) | E15: Issued (GBP)
A16: 2027 | C16: 1 | D16: 9.7618201e+08 | E16: 9.7618201e+08
A17: Description | B17: MV of Debt | C17: Asset Duplicated | D17: Maturity Date | E17: Amount Outstanding | F17: Issued Amount | G17: Coupon | I17: Coupon Class | J17: Country of Issue | K17: Currency | L17: ISIN | M17: RIC | N17: Cusip | O17: Issue Date | P17: Rank (Seniority) | Q17: Seniority (Legacy) | R17: Instrument Type | S17: Principal Index Link Flag | T17: Modified Duration | U17: Option Adjusted Duration | V17: Option Adjusted Spread | W17: Yield | X17: Yield Type | Y17: Yield Event | Z17: Yield Date | AA17: Last Price | AB17: Capital Tier | AC17: Government Bond Type | AD17: Is Convertible | AE17: Offering Type | AF17: Program Type | AG17: Domicile | AH17: Asset Status | AI17: Green Bonds | AJ17: Issuer | AK17: Collateral
A18: BTBRT / BT 1.500 23-Jun-2027 '27 MTN | B18: =E18*(AA18/100) -> 9.6404807e+08 | C18: -- | D18: 46561 | E18: 976182011 | F18: 976182011 | G18: 1.5 | I18: Fixed Coupon | J18: Eurobond | K18: Euro | L18: XS1637333748 | M18: GB163733374= | N18: -- | O18: 42909 | P18: Senior Unsecured | Q18: Senior Unsecured | R18: Note | S18: N | T18: 0.694946 | U18: 0.697701 | V18: 61.864224 | W18: 3.278186 | X18: IS | Y18: MAT | Z18: 46561 | AA18: 98.757 | AB18: N/A | AC18: -- | AD18: N | AE18: Regulation S | AF18: Medium Term Note Program | AG18: United Kingdom | AH18: Issued | AI18: N | AJ18: BRITISH TELECOMMUNICATIONS LTD | AK18: N/A
A19: BTBRT / BT 2.125 26-Sep-2028 '26 MTN | B19: =E19*(AA19/100) -> 4.1292075e+08 | C19: -- | D19: 47022 | E19: 424426961 | F19: 424426961 | G19: 2.125 | I19: Fixed Coupon | J19: Eurobond | K19: Euro | L19: XS1886403200 | M19: GB188640320= | N19: -- | O19: 43369 | P19: Senior Unsecured | Q19: Senior Unsecured | R19: Note | S19: N | T19: 1.914429 | U19: 1.91605 | V19: 48.09276 | W19: 3.574114 | X19: IS | Y19: MAT | Z19: 47022 | AA19: 97.289 | AB19: N/A | AC19: -- | AD19: N | AE19: Regulation S | AF19: Medium Term Note Program | AG19: United Kingdom | AH19: Issued | AI19: N | AJ19: BRITISH TELECOMMUNICATIONS LTD | AK19: N/A
A20: BTBRT / BT 5.125 04-Dec-2028 '28 | B20: =E20*(AA20/100) -> 5.2728656e+08 | C20: -- | D20: 47091 | E20: 529540812 | F20: 529540812 | G20: 5.125 | I20: Fixed Coupon | J20: United States | K20: US Dollar | L20: US111021AL54 | M20: 111021AL5= | N20: 111021AL5 | O20: 43438 | P20: Senior Unsecured | Q20: Senior Unsecured | R20: Note | S20: N | T20: 1.985975 | U20: 1.923427 | V20: 45.12328 | W20: 5.332504 | X20: CB | Y20: MAT | Z20: 47091 | AA20: 99.5743 | AB20: N/A | AC20: -- | AD20: N | AE20: Underwritten | AF20: -- | AG20: United Kingdom | AH20: Issued | AI20: N | AJ20: BRITISH TELECOMMUNICATIONS LTD | AK20: N/A
A21: BTBRT / BT 5.750 07-Dec-2028 | B21: =E21*(AA21/100) -> 604458000 | C21: -- | D21: 47094 | E21: 600000000 | F21: 600000000 | G21: 5.75 | I21: Fixed Coupon | J21: Eurobond | K21: British Pound | L21: XS0097283096 | M21: GB009728309= | N21: -- | O21: 36298 | P21: Senior Unsecured | Q21: Senior Unsecured | R21: Bond | S21: N | T21: 1.955589 | U21: 1.955589 | V21: 41.297924 | W21: 5.296972 | X21: IS | Y21: MAT | Z21: 47094 | AA21: 100.743 | AB21: N/A | AC21: -- | AD21: N | AE21: Regulation S | AF21: -- | AG21: United Kingdom | AH21: Issued | AI21: N | AJ21: BRITISH TELECOMMUNICATIONS LTD | AK21: N/A
A22: BTBRT / BT 1.125 12-Sep-2029 '29 MTN | B22: =E22*(AA22/100) -> 5.8856772e+08 | C22: -- | D22: 47373 | E22: 636640442 | F22: 636640442 | G22: 1.125 | I22: Fixed Coupon | J22: Eurobond | K22: Euro | L22: XS2051494495 | M22: GB205149449= | N22: -- | O22: 43720 | P22: Senior Unsecured | Q22: Senior Unsecured | R22: Note | S22: N | T22: 2.840907 | U22: 2.842622 | V22: 75.767184 | W22: 3.900222 | X22: IS | Y22: MAT | Z22: 47373 | AA22: 92.449 | AB22: N/A | AC22: -- | AD22: N | AE22: Regulation S | AF22: Medium Term Note Program | AG22: United Kingdom | AH22: Issued | AI22: N | AJ22: BRITISH TELECOMMUNICATIONS LTD | AK22: N/A
A23: BTBRT / BT 3.250 08-Nov-2029 '29 | B23: =E23*(AA23/100) -> 7.0681065e+08 | C23: -- | D23: 47430 | E23: 756486875 | F23: 756486875 | G23: 3.25 | I23: Fixed Coupon | J23: United States | K23: US Dollar | L23: US11102AAE10 | M23: 11102AAE1= | N23: 11102AAE1 | O23: 43777 | P23: Senior Unsecured | Q23: Senior Unsecured | R23: Note | S23: N | T23: 2.838259 | U23: 2.839643 | V23: 61.982311 | W23: 5.593184 | X23: CB | Y23: MAT | Z23: 47430 | AA23: 93.4333 | AB23: N/A | AC23: -- | AD23: N | AE23: Private placement-144A no reg rights | AF23: -- | AG23: United Kingdom | AH23: Issued | AI23: N | AJ23: BRITISH TELECOMMUNICATIONS LTD | AK23: N/A
A24: BTBRT / BT 9.625 15-Dec-2030 | B24: =E24*(AA24/100) -> 2.2919382e+09 | C24: -- | D24: 47832 | E24: 2019819956 | F24: 2118163250 | G24: 9.625 | I24: Variable Coupon | J24: United States | K24: US Dollar | L24: US111021AE12 | M24: GB012169353= | N24: 111021AE1 | O24: 36872 | P24: Senior Unsecured | Q24: Senior Unsecured | R24: Note | S24: N | T24: 3.402381 | U24: 3.402381 | V24: 92.610566 | W24: 5.942206 | X24: CB | Y24: MAT | Z24: 47833 | AA24: 113.4724 | AB24: N/A | AC24: -- | AD24: N | AE24: Underwritten | AF24: -- | AG24: United Kingdom | AH24: Issued | AI24: N | AJ24: BRITISH TELECOMMUNICATIONS LTD | AK24: N/A
A25: BTBRT / BT 3.750 13-May-2031 '31 MTN | B25: =E25*(AA25/100) -> 6.6893764e+08 | C25: -- | D25: 47981 | E25: 679083138 | F25: 679083138 | G25: 3.75 | I25: Fixed Coupon | J25: Eurobond | K25: Euro | L25: XS2582814039 | M25: GB258281403= | N25: -- | O25: 44970 | P25: Senior Unsecured | Q25: Senior Unsecured | R25: Note | S25: N | T25: 4.163538 | U25: 4.103998 | V25: 85.933943 | W25: 4.108838 | X25: IS | Y25: MAT | Z25: 47981 | AA25: 98.506 | AB25: N/A | AC25: -- | AD25: N | AE25: Regulation S | AF25: Medium Term Note Program | AG25: United Kingdom | AH25: Issued | AI25: N | AJ25: BRITISH TELECOMMUNICATIONS LTD | AK25: N/A
A26: BTBRT / BT 3.125 21-Nov-2031 '31 MTN | B26: =E26*(AA26/100) -> 445335000 | C26: -- | D26: 48173 | E26: 500000000 | F26: 500000000 | G26: 3.125 | H26: =(G26/100*B26)/1000000 -> 13.916719 | I26: Fixed Coupon | J26: Eurobond | K26: British Pound | L26: XS1720922415 | M26: GB172092241= | N26: -- | O26: 43060 | P26: Senior Unsecured | Q26: Senior Unsecured | R26: Note | S26: N | T26: 4.523907 | U26: 4.523411 | V26: 56.596281 | W26: 5.561804 | X26: IS | Y26: MAT | Z26: 48173 | AA26: 89.067 | AB26: N/A | AC26: -- | AD26: N | AE26: Regulation S | AF26: Medium Term Note Program | AG26: United Kingdom | AH26: Issued | AI26: N | AJ26: BRITISH TELECOMMUNICATIONS LTD | AK26: N/A
A27: BTBRT / BT 3.125 11-Feb-2032 '31 MTN | B27: =E27*(AA27/100) -> 6.8116368e+08 | C27: -- | D27: 48255 | E27: 721525834 | F27: 721525834 | G27: 3.125 | H27: =(G27/100*B27)/1000000 -> 21.286365 | I27: Fixed Coupon | J27: Eurobond | K27: Euro | L27: XS2994509706 | M27: GB299450970= | N27: -- | O27: 45699 | P27: Senior Unsecured | Q27: Senior Unsecured | R27: Note | S27: N | T27: 4.788758 | U27: 4.776965 | V27: 102.47166 | W27: 4.315463 | X27: IS | Y27: MAT | Z27: 48255 | AA27: 94.406 | AB27: N/A | AC27: -- | AD27: N | AE27: Regulation S | AF27: Euro Medium Term Note Program | AG27: United Kingdom | AH27: Issued | AI27: N | AJ27: BRITISH TELECOMMUNICATIONS LTD | AK27: N/A
A28: BTBRT / BT 3.375 30-Aug-2032 '32 MTN | B28: =E28*(AA28/100) -> 4.027727e+08 | C28: -- | D28: 48456 | E28: 424426961 | F28: 424426961 | G28: 3.375 | H28: =(G28/100*B28)/1000000 -> 13.593579 | I28: Fixed Coupon | J28: Eurobond | K28: Euro | L28: XS2496028924 | M28: GB249602892= | N28: -- | O28: 44803 | P28: Senior Unsecured | Q28: Senior Unsecured | R28: Note | S28: N | T28: 5.293195 | U28: 5.271123 | V28: 105.26451 | W28: 4.374098 | X28: IS | Y28: MAT | Z28: 48456 | AA28: 94.898 | AB28: N/A | AC28: -- | AD28: N | AE28: Regulation S | AF28: Medium Term Note Program | AG28: United Kingdom | AH28: Issued | AI28: N | AJ28: BRITISH TELECOMMUNICATIONS LTD | AK28: N/A
A29: BTBTF / BT 3.375 17-Nov-2032 '32 MTN | B29: =E29*(AA29/100) -> 6.8241913e+08 | C29: -- | D29: 48535 | E29: 721525834 | F29: 721525834 | G29: 3.375 | H29: =(G29/100*B29)/1000000 -> 23.031646 | I29: Fixed Coupon | J29: Eurobond | K29: Euro | L29: XS3227880021 | M29: GB322788002= | N29: -- | O29: 45978 | P29: Senior Unsecured | Q29: Senior Unsecured | R29: Note | S29: N | T29: 5.321028 | U29: 5.304801 | V29: 106.82639 | W29: 4.404324 | X29: IS | Y29: MAT | Z29: 48535 | AA29: 94.58 | AB29: N/A | AC29: -- | AD29: N | AE29: Regulation S | AF29: Euro Medium Term Note Program | AG29: United Kingdom | AH29: Issued | AI29: N | AJ29: BT FINANCE PLC | AK29: N/A
A30: BTBRT / BT 4.250 06-Jan-2033 '32 MTN | B30: =E30*(AA30/100) -> 7.1282423e+08 | C30: -- | D30: 48585 | E30: 721525834 | F30: 721525834 | G30: 4.25 | H30: =(G30/100*B30)/1000000 -> 30.29503 | I30: Fixed Coupon | J30: Eurobond | K30: Euro | L30: XS2675225531 | M30: GB267522553= | N30: -- | O30: 45175 | P30: Senior Unsecured | Q30: Senior Unsecured | R30: Note | S30: N | T30: 5.322946 | U30: 5.268976 | V30: 112.28518 | W30: 4.472195 | X30: IS | Y30: MAT | Z30: 48585 | AA30: 98.794 | AB30: N/A | AC30: -- | AD30: N | AE30: Regulation S | AF30: Medium Term Note Program | AG30: United Kingdom | AH30: Issued | AI30: N | AJ30: BRITISH TELECOMMUNICATIONS LTD | AK30: N/A
A31: BTBRT / BT 4.710 01-Mar-2033 MTN | B31: =E31*(AA31/100) -> 73882257 | C31: -- | D31: 48639 | E31: 78928976 | F31: 78928976 | G31: 4.71 | H31: =(G31/100*B31)/1000000 -> 3.4798543 | I31: Fixed Coupon | J31: Eurobond | K31: Norwegian Krone | L31: XS3168818238 | M31: GB316881823= | N31: -- | O31: 45901 | P31: Senior Unsecured | Q31: Unsecured | R31: Note | S31: N | T31: 4.476715 | U31: 6.052388 | V31: 98.427008 | W31: 5.743384 | X31: IS | Y31: MAT | Z31: 48639 | AA31: 93.606 | AB31: N/A | AC31: -- | AD31: N | AE31: Underwritten-Agent | AF31: Medium Term Note Program | AG31: United Kingdom | AH31: Issued | AI31: N | AJ31: BRITISH TELECOMMUNICATIONS LTD | AK31: N/A
