Workbook
Name Audit_check: Guide!$G$133
Name Base_year: Guide!$E$32
Name Circular_Toggle: Guide!$E$19
Name company: Guide!$E$11
Name currency: Guide!$E$20
Name Date_last_historical: Guide!$E$28
Name Floating: "Floating"
Name Forecast_year: Guide!$E$33
Name l_scenarios: Scn!$D$16:$D$18
Name Last_updated: Guide!$E$22
Name Live_Scenario: Scn!$D$15
Name Modeler: Guide!$E$23
Name models: Guide!$B$49
Name months_in_period: Guide!$E$31
Name onths_in_period: Guide!$E$31
Name S_Scenarios: Scn!$F$15
Name Version: Guide!$E$21

Sheet Cover
D9: =company -> Nestle Nigeria
D10: ="Financial model for "&Base_year+1&" - "&Forecast_year -> Financial model for 2023 - 2027
D14: WIP:
D15: Live Scenario yet to be automated
D16: Audit Check

Sheet Guide
D2: =company -> Nestle Nigeria | O2: =Version -> Ver 1.01.
D3: =models -> Model Style Guide
B8: Model Details
C9: This section highlights general information about the company being modeled and technical information about thee project
C10: Company Information
D11: Company Name | E11: Nestle Nigeria
D12: Purpose of the Model | E12: Support 5 year strategic plan
D13: Industry | E13: FMCG
D14: Location | E14: Nigeria
C16: Model Information
D17: Model Owner | E17: Srategic mgt team
D18: Circularity in Model | E18: Deliberate circularity in th interest income and interest expense lines of theCalculation sheet
D19: Iteration Toggle | E19: FALSE
D20: Currency | E20: ₦ Th's
D21: Version | E21: =INDEX(D:D,MATCH("Ω",D:D,1)) -> Ver 1.01. | F21: Ω
D22: Last Updated | E22: =INDEX(E:E,MATCH("Ω",E:E,1)) -> Date Modified
D23: Current Modeler | E23: =INDEX(F:F,MATCH("Ω",F:F,1)) -> Opeoluwa Kuku
B25: Model Structure & Navigation
C27: Major Timings
D28: Latest Historical Financials end Date | E28: 44926
D29: Model Forecast period | E29: 5
D30: Months in the Year | E30: 12
D31: Months in each time period | E31: 12
D32: Historical Financial Year | E32: =YEAR(E28) -> 2022
D33: Forecast Period End Year | E33: =E32+E29 -> 2027
C35: Sheet Structure
D36: Cover
D37: Guide
D38: Summary
D39: Historicals & Restructured Financials
D40: Inputs & Assumptions
D41: Scenario Inputs
D42: Calculatios
D43: Income Statement
D44: Balance Sheet
D45: Cash Flow Statement
D46: Ratio Analysis
D47: Valuation Analysis
B49: Model Style Guide
C50: This style guide will help you efficiently navigate through and interprete sections of this model
...

Sheet Summary
B2: =company -> Nestle Nigeria
C3: Summary
D4: =Live_Scenario -> Live Scenario: Base Case | H4: Start Date | J4: =I5+1 -> 43831 | K4: =J5+1 -> 44197 | L4: =K5+1 -> 44562 | M4: =L5+1 -> 44927 | N4: =M5+1 -> 45292 | O4: =N5+1 -> 45658 | P4: =O5+1 -> 46023 | Q4: =P5+1 -> 46388
D5: ="Audit Check: "& Audit_check -> Audit Check: OK | H5: End Date | I5: =EOMONTH(J5,-months_in_period) -> 43830 | J5: =EOMONTH(K5,-months_in_period) -> 44196 | K5: =EOMONTH(L5,-months_in_period) -> 44561 | L5: =Date_last_historical -> 44926 | M5: =EOMONTH(L5,months_in_period) -> 45291 | N5: =EOMONTH(M5,months_in_period) -> 45657 | O5: =EOMONTH(N5,months_in_period) -> 46022 | P5: =EOMONTH(O5,months_in_period) -> 46387 | Q5: =EOMONTH(P5,months_in_period) -> 46752
D6: Actual | J6: =(J5<=Date_last_historical)*1 -> 1 | K6: =(K5<=Date_last_historical)*1 -> 1 | L6: =(L5<=Date_last_historical)*1 -> 1 | M6: =(M5<=Date_last_historical)*1 -> 0 | N6: =(N5<=Date_last_historical)*1 -> 0 | O6: =(O5<=Date_last_historical)*1 -> 0 | P6: =(P5<=Date_last_historical)*1 -> 0 | Q6: =(Q5<=Date_last_historical)*1 -> 0
D7: Forecast | J7: =(J5>=Date_last_historical)*1 -> 0 | K7: =(K5>=Date_last_historical)*1 -> 0 | L7: =(L5>Date_last_historical)*1 -> 0 | M7: =(M5>=Date_last_historical)*1 -> 1 | N7: =(N5>=Date_last_historical)*1 -> 1 | O7: =(O5>=Date_last_historical)*1 -> 1 | P7: =(P5>=Date_last_historical)*1 -> 1 | Q7: =(Q5>=Date_last_historical)*1 -> 1
D8: Description | E8: Units | F8: Inputs | I8: Row Totals | J8: Hist | K8: Hist | L8: Hist | M8: Proj | N8: Proj | O8: Proj | P8: Proj | Q8: Proj

Sheet Hist
B2: =company -> Nestle Nigeria
C3: Historicals & Restructured Financials
D4: =Live_Scenario -> Live Scenario: Base Case | H4: Start Date | J4: =I5+1 -> 43831 | K4: =J5+1 -> 44197 | L4: =K5+1 -> 44562 | M4: =L5+1 -> 44927 | N4: =M5+1 -> 45292 | O4: =N5+1 -> 45658 | P4: =O5+1 -> 46023 | Q4: =P5+1 -> 46388
D5: ="Audit Check: "& Audit_check -> Audit Check: OK | H5: End Date | I5: =EOMONTH(J5,-months_in_period) -> 43830 | J5: =EOMONTH(K5,-months_in_period) -> 44196 | K5: =EOMONTH(L5,-months_in_period) -> 44561 | L5: =Date_last_historical -> 44926 | M5: =EOMONTH(L5,months_in_period) -> 45291 | N5: =EOMONTH(M5,months_in_period) -> 45657 | O5: =EOMONTH(N5,months_in_period) -> 46022 | P5: =EOMONTH(O5,months_in_period) -> 46387 | Q5: =EOMONTH(P5,months_in_period) -> 46752
D6: Actual | J6: =(J5<=Date_last_historical)*1 -> 1 | K6: =(K5<=Date_last_historical)*1 -> 1 | L6: =(L5<=Date_last_historical)*1 -> 1 | M6: =(M5<=Date_last_historical)*1 -> 0 | N6: =(N5<=Date_last_historical)*1 -> 0 | O6: =(O5<=Date_last_historical)*1 -> 0 | P6: =(P5<=Date_last_historical)*1 -> 0 | Q6: =(Q5<=Date_last_historical)*1 -> 0
D7: Forecast | J7: =(J5>Date_last_historical)*1 -> 0 | K7: =(K5>Date_last_historical)*1 -> 0 | L7: =(L5>Date_last_historical)*1 -> 0 | M7: =(M5>Date_last_historical)*1 -> 1 | N7: =(N5>Date_last_historical)*1 -> 1 | O7: =(O5>Date_last_historical)*1 -> 1 | P7: =(P5>Date_last_historical)*1 -> 1 | Q7: =(Q5>Date_last_historical)*1 -> 1
D8: Description | E8: Units | F8: Inputs | I8: Row Totals | J8: Hist | K8: Hist | L8: Hist | M8: Proj | N8: Proj | O8: Proj | P8: Proj | Q8: Proj
B10: Financial Statements - Per Audit
B11: These are the financial statement numbers extracted from the latest audited accounts (As is)
C12: Statement of Profit or loss and other Comprehensive Income
D13: Revenue | E13: =currency -> ₦ Th's | J13: 287084087 | K13: 351822329 | L13: 446819260
D14: Cost of sales | E14: =currency -> ₦ Th's | J14: -167872616 | K14: -219985914 | L14: -291054270
D15: Gross Profit | E15: =currency -> ₦ Th's | J15: 119211471 | K15: 131836414 | L15: 155764990
D16: Marketing and distribution expenses | E16: =currency -> ₦ Th's | J16: -43843396 | K16: -48097581 | L16: -57331351
D17: Administrative expenses | E17: =currency -> ₦ Th's | J17: -10949492 | K17: -11494450 | L17: -11538113
B18: Need to model this newkline | D18: Impairment of financial assets | J18: 0 | K18: -278438 | L18: -29043
D19: Results from operating activities | E19: =currency -> ₦ Th's | J19: 64418583 | K19: 71965945 | L19: 86866483
D20: Finance income | E20: =currency -> ₦ Th's | J20: 646546 | K20: 1987042 | L20: 4777113
D21: Finance costs | E21: =currency -> ₦ Th's | J21: -4426686 | K21: -12077645 | L21: -20534225
D22: Net finance cost | E22: =currency -> ₦ Th's | J22: -3780140 | K22: -10090603 | L22: -15757112
D23: Profit before income tax | E23: =currency -> ₦ Th's | J23: 60638443 | K23: 61875342 | L23: 71109371
D24: Income tax expense | E24: =currency -> ₦ Th's | J24: -21426418 | K24: -21838065 | L24: -22143883
D25: Profit for the year | E25: =currency -> ₦ Th's | J25: 39212025 | K25: =SUM(K13:K14,K16:K18,K20:K21,K24) -> 40037278 | L25: 48965488
C27: Statement of Financial Position
D28: Assets
D29: Property, plant and equipment | E29: =currency -> ₦ Th's | J29: 87265836 | K29: 98964157 | L29: =116739370-1+N("Rounding error per audited account") -> 116739369
D30: Right of Use Assets | E30: =currency -> ₦ Th's | J30: 5054528 | K30: 4848732 | L30: 4976420
D31: Long term receivables | E31: =currency -> ₦ Th's | J31: 2363177 | K31: 2501289 | L31: 2816337
D32: Total non-current assets | E32: =currency -> ₦ Th's | J32: =SUM(J29:J31) -> 94683541 | K32: =SUM(K29:K31) -> 106314178 | L32: =SUM(L29:L31) -> 124532126
D33: Inventories | E33: =currency -> ₦ Th's | J33: 52222267 | K33: 58964125 | L33: 88340532
D34: Right of return assets | E34: =currency -> ₦ Th's | J34: 52263 | K34: 45443 | L34: 72879
D35: Trade and other receivables | E35: =currency -> ₦ Th's | J35: 39555290 | K35: =43302758-2+N(("rounding error per audit")) -> 43302756 | L35: 82237026
D36: Prepayments | E36: =currency -> ₦ Th's | J36: 968426 | K36: 1093841 | L36: 1929038
D37: Cash and short term-deposit | E37: =currency -> ₦ Th's | J37: 58703209 | K37: 100518159 | L37: 117932430
D38: Total current assets | E38: =currency -> ₦ Th's | J38: =SUM(J33:J37) -> 151501455 | K38: =SUM(K33:K37) -> 203924324 | L38: =SUM(L33:L37) -> 290511905
D39: Total assets | E39: =currency -> ₦ Th's | J39: =J32+J38 -> 246184996 | K39: =K32+K38 -> 310238502 | L39: =L32+L38 -> 415044031
D40: Equity
D41: Share capital | E41: =currency -> ₦ Th's | J41: 396328 | K41: 396328 | L41: 396328
D42: Share premium | E42: =currency -> ₦ Th's | J42: 32262 | K42: 32262 | L42: 32262
D43: Share based payment reserve | E43: =currency -> ₦ Th's | J43: 113811 | K43: =113459-3+N("rounding error per audited") -> 113456 | L43: 90127
...

Sheet Inps
B2: =company -> Nestle Nigeria
C3: Inputs & Assumptions
D4: =Live_Scenario -> Live Scenario: Base Case | H4: Start Date | J4: =I5+1 -> 43831 | K4: =J5+1 -> 44197 | L4: =K5+1 -> 44562 | M4: =L5+1 -> 44927 | N4: =M5+1 -> 45292 | O4: =N5+1 -> 45658 | P4: =O5+1 -> 46023 | Q4: =P5+1 -> 46388
D5: ="Audit Check: "& Audit_check -> Audit Check: OK | H5: End Date | I5: =EOMONTH(J5,-months_in_period) -> 43830 | J5: =EOMONTH(K5,-months_in_period) -> 44196 | K5: =EOMONTH(L5,-months_in_period) -> 44561 | L5: =Date_last_historical -> 44926 | M5: =EOMONTH(L5,months_in_period) -> 45291 | N5: =EOMONTH(M5,months_in_period) -> 45657 | O5: =EOMONTH(N5,months_in_period) -> 46022 | P5: =EOMONTH(O5,months_in_period) -> 46387 | Q5: =EOMONTH(P5,months_in_period) -> 46752
D6: Actual | J6: =(J5<=Date_last_historical)*1 -> 1 | K6: =(K5<=Date_last_historical)*1 -> 1 | L6: =(L5<=Date_last_historical)*1 -> 1 | M6: =(M5<=Date_last_historical)*1 -> 0 | N6: =(N5<=Date_last_historical)*1 -> 0 | O6: =(O5<=Date_last_historical)*1 -> 0 | P6: =(P5<=Date_last_historical)*1 -> 0 | Q6: =(Q5<=Date_last_historical)*1 -> 0
D7: Forecast | J7: =(J5>=Date_last_historical)*1 -> 0 | K7: =(K5>=Date_last_historical)*1 -> 0 | L7: =(L5>Date_last_historical)*1 -> 0 | M7: =(M5>=Date_last_historical)*1 -> 1 | N7: =(N5>=Date_last_historical)*1 -> 1 | O7: =(O5>=Date_last_historical)*1 -> 1 | P7: =(P5>=Date_last_historical)*1 -> 1 | Q7: =(Q5>=Date_last_historical)*1 -> 1
D8: Description | E8: Units | F8: Inputs | I8: Row Totals | J8: Hist | K8: Hist | L8: Hist | M8: Proj | N8: Proj | O8: Proj | P8: Proj | Q8: Proj
B10: General Assumptions
C11: Assumptions in this section generally affect multiple sections and calculations of the financial model
C12: Timings and Counters
D13: Simple Counter | E13: Counter | J13: =K13-1 -> -2 | K13: =L13-1 -> -1 | L13: =0 -> 0 | M13: =L13+1 -> 1 | N13: =M13+1 -> 2 | O13: =N13+1 -> 3 | P13: =O13+1 -> 4 | Q13: =P13+1 -> 5
D14: Year | E14: Year | J14: =YEAR(J5) -> 2020 | K14: =YEAR(K5) -> 2021 | L14: =YEAR(L5) -> 2022 | M14: =YEAR(M5) -> 2023 | N14: =YEAR(N5) -> 2024 | O14: =YEAR(O5) -> 2025 | P14: =YEAR(P5) -> 2026 | Q14: =YEAR(Q5) -> 2027
D15: Days in the year | E15: Days | J15: =J5-I5 -> 366 | K15: =K5-J5 -> 365 | L15: =L5-K5 -> 365 | M15: =M5-L5 -> 365 | N15: =N5-M5 -> 366 | O15: =O5-N5 -> 365 | P15: =P5-O5 -> 365 | Q15: =Q5-P5 -> 365
B18: Profit Or Loss Assumptions
C19: Assumptions in this section generally affect multiple sections and calculations of the financial model
D22: =Hist!D99 -> Revenue | E22: yoy % growth from scn sheet | J22: 0 | K22: =(Hist!K13/Hist!J13)-1 -> 0.22550272 | L22: =(Hist!L13/Hist!K13)-1 -> 0.27001393 | M22: =Scn!M23 -> 0.22 | N22: =Scn!N23 -> 0.22 | O22: =Scn!O23 -> 0.22 | P22: =Scn!P23 -> 0.22 | Q22: =Scn!Q23 -> 0.22
D23: =Hist!D100 -> Cost of Sales | E23: % of Revenue | J23: =Hist!J100/Hist!J99 -> 0.56710781 | K23: =Hist!K100/Hist!K99 -> 0.60910404 | L23: =Hist!L100/Hist!L99 -> 0.63685179 | M23: =Scn!M29 -> 0.6571 | N23: =Scn!N29 -> 0.6571 | O23: =Scn!O29 -> 0.6571 | P23: =Scn!P29 -> 0.6571 | Q23: =Scn!Q29 -> 0.6571
D24: =Hist!D101 -> Gross Profit
D25: =Hist!D102 -> SG&A Expenses | E25: % of Revenue | J25: =Hist!J102/Hist!J99 -> 0.18302324 | K25: =Hist!K102/Hist!K99 -> 0.16291294 | L25: =Hist!L102/Hist!L99 -> 0.14848819 | M25: =Scn!M35 -> 0.14848819 | N25: =Scn!N35 -> 0.14848819 | O25: =Scn!O35 -> 0.14848819 | P25: =Scn!P35 -> 0.14848819 | Q25: =Scn!Q35 -> 0.14848819
D27: =Hist!D104 -> Depreciation | E27: % of previous PP&E | J27: 0 | K27: =Hist!K104/Hist!J120 -> 0.086277075 | L27: =Hist!L104/Hist!K120 -> 0.086874627 | M27: 0.0957 | N27: 0.0957 | O27: 0.0957 | P27: 0.0957 | Q27: 0.0957
D28: =Hist!D105 -> Impairement | E28: Fixed amount | J28: =Hist!J105 -> 0 | K28: =Hist!K105 -> 278438 | L28: =Hist!L105 -> 29043 | M28: 29043 | N28: 29043 | O28: 29043 | P28: 29043 | Q28: 29043
D30: =Hist!D107 -> Interest income
D31: =Hist!D108 -> Interest Expense
D32: =Hist!D109 -> Net Foreign Exchange Loss | E32: Fixed amount | J32: =Hist!J109 -> 1728282 | K32: =Hist!K109 -> 4735034 | L32: =Hist!L109 -> 7851981 | M32: 7851981 | N32: 7851981 | O32: 7851981 | P32: 7851981 | Q32: 7851981
D34: =Hist!D111 -> Current Tax Expense | E34: Statutory Tax Rate | J34: 0.32 | K34: 0.32 | L34: 0.32 | M34: 0.32 | N34: 0.32 | O34: 0.32 | P34: 0.32 | Q34: 0.32
D35: Reduction in EBT for Timing difference | E35: Implied reduction on EBT based on govt financials | J35: =Hist!J112/Inps!J34 -> -1476850 | K35: =Hist!K112/Inps!K34 -> 1885506.2 | L35: =Hist!L112/Inps!L34 -> 7082612.5 | M35: 3300000 | N35: 3300000 | O35: 3300000 | P35: 3300000 | Q35: 3300000
D36: Total Tax | E36: Effective Tax Rate | J36: =(Hist!J112+Hist!J111)/Hist!J110 -> 0.3533471 | K36: =(Hist!K112+Hist!K111)/Hist!K110 -> 0.35293647 | L36: =(Hist!L112+Hist!L111)/Hist!L110 -> 0.31140597
D37: Dividend Payout Ratio | E37: Dividend Payout Ratio | M37: 0.8 | N37: 0.8 | O37: 0.8 | P37: 0.8 | Q37: 0.8
B41: Balance Sheet Assumptions
C42: Assumptions in this section generally affect multiple sections and calculations of the financial model
B43: =Hist!B118 -> Assets
C44: =Hist!C119 -> Non - Current Assets
D45: =Hist!D120 -> PP&E
D46: Maintanable Capex | E46: Inflation factor | M46: =Scn!M41 -> 1.2 | N46: =Scn!N41 -> 1.2 | O46: =Scn!O41 -> 1.2 | P46: =Scn!P41 -> 1.2 | Q46: =Scn!Q41 -> 1.2 | R46: replacing currentt capex for maintaining production
D47: Incremental Capex | E47: Fixed factor | M47: 0 | N47: 0 | O47: 0 | P47: 0 | Q47: 0 | R47: You can also use historicals for determining the rate at which a business acquires new properties every year and use sales as the driver… e.g fast food restaurants and new locations
C48: =Hist!C123 -> Current Assets
D49: =Hist!D124 -> Trade Receivables | E49: % of revenues | J49: =ABS((L49/K49)-1) -> 0.028404045 | K49: =Hist!K124/Hist!K99 -> 0.011955512 | L49: =Hist!L124/Hist!L99 -> 0.012295097 | M49: 0.0694 | N49: 0.0694 | O49: 0.0694 | P49: 0.0694 | Q49: 0.0694 | R49: =L49/K49-1 -> 0.028404045
D50: =Hist!D125 -> Staff Loans | E50: Ending Balance | J50: =ABS((L50/K50)-1) -> 0.041318139 | K50: =Hist!K125 -> 2870047 | L50: =Hist!L125 -> 2988632 | M50: 2866469 | N50: 2866469 | O50: 2866469 | P50: 2866469 | Q50: 2866469 | R50: predictive power, should idealy be under 1%
D51: =Hist!D126 -> Deposit with Company registrars for dividend | E51: % EAT | J51: =ABS((L51/K51)-1) -> 0.25936443 | K51: =Hist!K126/Hist!K113 -> 0.069965346 | L51: =Hist!L126/Hist!L113 -> 0.051818824 | M51: 0.0545 | N51: 0.0545 | O51: 0.0545 | P51: 0.0545 | Q51: 0.0545
D52: =Hist!D127 -> Advance payment to suppliers | E52: & COGS | J52: =ABS((L52/K52)-1) -> 0.50433835 | K52: =Hist!K127/Hist!K100 -> 0.15989016 | L52: =Hist!L127/Hist!L100 -> 0.2405289 | M52: 0.21 | N52: 0.21 | O52: 0.21 | P52: 0.21 | Q52: 0.21
...

Sheet Scn
B2: =company -> Nestle Nigeria
C3: Scenario Inputs
D4: =Live_Scenario -> Live Scenario: Base Case | H4: Start Date | J4: =I5+1 -> 43831 | K4: =J5+1 -> 44197 | L4: =K5+1 -> 44562 | M4: =L5+1 -> 44927 | N4: =M5+1 -> 45292 | O4: =N5+1 -> 45658 | P4: =O5+1 -> 46023 | Q4: =P5+1 -> 46388
D5: ="Audit Check: "& Audit_check -> Audit Check: OK | H5: End Date | I5: =EOMONTH(J5,-months_in_period) -> 43830 | J5: =EOMONTH(K5,-months_in_period) -> 44196 | K5: =EOMONTH(L5,-months_in_period) -> 44561 | L5: =Date_last_historical -> 44926 | M5: =EOMONTH(L5,months_in_period) -> 45291 | N5: =EOMONTH(M5,months_in_period) -> 45657 | O5: =EOMONTH(N5,months_in_period) -> 46022 | P5: =EOMONTH(O5,months_in_period) -> 46387 | Q5: =EOMONTH(P5,months_in_period) -> 46752
D6: Actual | J6: =(J5<=Date_last_historical)*1 -> 1 | K6: =(K5<=Date_last_historical)*1 -> 1 | L6: =(L5<=Date_last_historical)*1 -> 1 | M6: =(M5<=Date_last_historical)*1 -> 0 | N6: =(N5<=Date_last_historical)*1 -> 0 | O6: =(O5<=Date_last_historical)*1 -> 0 | P6: =(P5<=Date_last_historical)*1 -> 0 | Q6: =(Q5<=Date_last_historical)*1 -> 0
D7: Forecast | J7: =(J5>=Date_last_historical)*1 -> 0 | K7: =(K5>=Date_last_historical)*1 -> 0 | L7: =(L5>Date_last_historical)*1 -> 0 | M7: =(M5>=Date_last_historical)*1 -> 1 | N7: =(N5>=Date_last_historical)*1 -> 1 | O7: =(O5>=Date_last_historical)*1 -> 1 | P7: =(P5>=Date_last_historical)*1 -> 1 | Q7: =(Q5>=Date_last_historical)*1 -> 1
D8: Description | E8: Units | F8: Inputs | I8: Row Totals | J8: Hist | K8: Hist | L8: Hist | M8: Proj | N8: Proj | O8: Proj | P8: Proj | Q8: Proj
B10: Scenario & Sensitiviy Analysis Tool
C11: This section enables us to build multiple scenarios for highly uncertain and critical assumptions to assess their impacts on the model outputs
C13: Scenario Picker
D15: =_xlfn.CONCAT("Live Scenario: ",INDEX(l_scenarios,S_Scenarios,1)) -> Live Scenario: Base Case | F15: 1
D16: Base Case | R16: ctrl+shift+7 to turn items into a list
D17: Best Case
D18: Worst Case
C22: Revenue Scenarios (YoY Growth Rate)
D23: =_xlfn.CONCAT("Used in the model: ",INDEX(l_scenarios,S_Scenarios,1)) -> Used in the model: Base Case | M23: {=INDEX(M24:M26,S_Scenarios,1)} -> 0.22 | N23: {=INDEX(N24:N26,S_Scenarios,1)} -> 0.22 | O23: {=INDEX(O24:O26,S_Scenarios,1)} -> 0.22 | P23: {=INDEX(P24:P26,S_Scenarios,1)} -> 0.22 | Q23: {=INDEX(Q24:Q26,S_Scenarios,1)} -> 0.22
D24: =$D$16 -> Base Case | E24: % | M24: 0.22 | N24: 0.22 | O24: 0.22 | P24: 0.22 | Q24: 0.22
D25: =$D$17 -> Best Case | E25: % | M25: 0.27 | N25: 0.27 | O25: 0.27 | P25: 0.27 | Q25: 0.27
D26: =$D$18 -> Worst Case | E26: % | K26: Based on the 2019 model, which may be a better representation of the growth prospect of the company before the naira devaluation | M26: 0.1 | N26: 0.1 | O26: 0.1 | P26: 0.1 | Q26: 0.1
C28: COGS Scenarios (% of Revenue)
D29: =_xlfn.CONCAT("Used in the model: ",INDEX(l_scenarios,S_Scenarios,1)) -> Used in the model: Base Case | M29: {=INDEX(M30:M32,S_Scenarios,1)} -> 0.6571 | N29: {=INDEX(N30:N32,S_Scenarios,1)} -> 0.6571 | O29: {=INDEX(O30:O32,S_Scenarios,1)} -> 0.6571 | P29: {=INDEX(P30:P32,S_Scenarios,1)} -> 0.6571 | Q29: {=INDEX(Q30:Q32,S_Scenarios,1)} -> 0.6571
D30: =$D$16 -> Base Case | E30: % | M30: 0.6571 | N30: 0.6571 | O30: 0.6571 | P30: 0.6571 | Q30: 0.6571
D31: =$D$17 -> Best Case | E31: % | M31: 0.6044 | N31: 0.6044 | O31: 0.6044 | P31: 0.6044 | Q31: 0.6044
D32: =$D$18 -> Worst Case | E32: % | M32: 0.69 | N32: 0.69 | O32: 0.69 | P32: 0.69 | Q32: 0.69
C34: SG&A Scenarios (% of Revenue)
D35: =_xlfn.CONCAT("Used in the model: ",INDEX(l_scenarios,S_Scenarios,1)) -> Used in the model: Base Case | M35: {=INDEX(M36:M38,S_Scenarios,1)} -> 0.14848819 | N35: {=INDEX(N36:N38,S_Scenarios,1)} -> 0.14848819 | O35: {=INDEX(O36:O38,S_Scenarios,1)} -> 0.14848819 | P35: {=INDEX(P36:P38,S_Scenarios,1)} -> 0.14848819 | Q35: {=INDEX(Q36:Q38,S_Scenarios,1)} -> 0.14848819
D36: =$D$16 -> Base Case | E36: % | M36: 0.14848819 | N36: 0.14848819 | O36: 0.14848819 | P36: 0.14848819 | Q36: 0.14848819
D37: =$D$17 -> Best Case | E37: % | M37: =M36-1% -> 0.13848819 | N37: =N36-1% -> 0.13848819 | O37: =O36-1% -> 0.13848819 | P37: =P36-1% -> 0.13848819 | Q37: =Q36-1% -> 0.13848819
D38: =$D$18 -> Worst Case | E38: % | M38: =M36+1% -> 0.15848819 | N38: =N36+1% -> 0.15848819 | O38: =O36+1% -> 0.15848819 | P38: =P36+1% -> 0.15848819 | Q38: =Q36+1% -> 0.15848819
C40: Maintainable CAPEX Scenario
D41: =_xlfn.CONCAT("Used in the model: ",INDEX(l_scenarios,S_Scenarios,1)) -> Used in the model: Base Case | M41: {=INDEX(M42:M44,S_Scenarios,1)} -> 1.2 | N41: {=INDEX(N42:N44,S_Scenarios,1)} -> 1.2 | O41: {=INDEX(O42:O44,S_Scenarios,1)} -> 1.2 | P41: {=INDEX(P42:P44,S_Scenarios,1)} -> 1.2 | Q41: {=INDEX(Q42:Q44,S_Scenarios,1)} -> 1.2
D42: =$D$16 -> Base Case | E42: % | M42: 1.2 | N42: 1.2 | O42: 1.2 | P42: 1.2 | Q42: 1.2
D43: =$D$17 -> Best Case | E43: % | M43: 1.15 | N43: 1.15 | O43: 1.15 | P43: 1.15 | Q43: 1.15
D44: =$D$18 -> Worst Case | E44: % | M44: 1.25 | N44: 1.25 | O44: 1.25 | P44: 1.25 | Q44: 1.25

Sheet Calc
B2: =company -> Nestle Nigeria
C3: Calculations
D4: =Live_Scenario -> Live Scenario: Base Case | H4: Start Date | J4: =I5+1 -> 43831 | K4: =J5+1 -> 44197 | L4: =K5+1 -> 44562 | M4: =L5+1 -> 44927 | N4: =M5+1 -> 45292 | O4: =N5+1 -> 45658 | P4: =O5+1 -> 46023 | Q4: =P5+1 -> 46388
D5: ="Audit Check: "& Audit_check -> Audit Check: OK | H5: End Date | I5: =EOMONTH(J5,-months_in_period) -> 43830 | J5: =EOMONTH(K5,-months_in_period) -> 44196 | K5: =EOMONTH(L5,-months_in_period) -> 44561 | L5: =Date_last_historical -> 44926 | M5: =EOMONTH(L5,months_in_period) -> 45291 | N5: =EOMONTH(M5,months_in_period) -> 45657 | O5: =EOMONTH(N5,months_in_period) -> 46022 | P5: =EOMONTH(O5,months_in_period) -> 46387 | Q5: =EOMONTH(P5,months_in_period) -> 46752
D6: Actual | J6: =(J5<=Date_last_historical)*1 -> 1 | K6: =(K5<Date_last_historical)*1 -> 1 | L6: =(L5<=Date_last_historical)*1 -> 1 | M6: =(M5<=Date_last_historical)*1 -> 0 | N6: =(N5<=Date_last_historical)*1 -> 0 | O6: =(O5<=Date_last_historical)*1 -> 0 | P6: =(P5<=Date_last_historical)*1 -> 0 | Q6: =(Q5<=Date_last_historical)*1 -> 0
D7: Forecast | J7: =(J5>=Date_last_historical)*1 -> 0 | K7: =(K5>=Date_last_historical)*1 -> 0 | L7: =(L5>Date_last_historical)*1 -> 0 | M7: =(M5>=Date_last_historical)*1 -> 1 | N7: =(N5>=Date_last_historical)*1 -> 1 | O7: =(O5>=Date_last_historical)*1 -> 1 | P7: =(P5>=Date_last_historical)*1 -> 1 | Q7: =(Q5>=Date_last_historical)*1 -> 1
D8: Description | E8: Units | F8: Inputs | I8: Row Totals | J8: Hist | K8: Hist | L8: Hist | M8: Proj | N8: Proj | O8: Proj | P8: Proj | Q8: Proj
B10: Profit or Loss Calculations
C11: Calculations for the profit or loss projections
C12: Revenue Computations
D13: =Inps!D22 -> Revenue | E13: =Inps!E22 -> yoy % growth from scn sheet | M13: =Inps!M22 -> 0.22 | N13: =Inps!N22 -> 0.22 | O13: =Inps!O22 -> 0.22 | P13: =Inps!P22 -> 0.22 | Q13: =Inps!Q22 -> 0.22
D14: Revenue Calculations | E14: =currency -> ₦ Th's | J14: =Hist!J99 -> 287084087 | K14: =Hist!K99 -> 351822329 | L14: =Hist!L99 -> 446819260 | M14: =L14*(1+M13) -> 5.451195e+08 | N14: =M14*(1+N13) -> 6.6504579e+08 | O14: =N14*(1+O13) -> 8.1135586e+08 | P14: =O14*(1+P13) -> 9.8985415e+08 | Q14: =P14*(1+Q13) -> 1.2076221e+09
C17: COGS & SG&A Computations
D18: Assumptions
D19: =Inps!D23 -> Cost of Sales | E19: =Inps!E23 -> % of Revenue | M19: =Inps!M23 -> 0.6571 | N19: =Inps!N23 -> 0.6571 | O19: =Inps!O23 -> 0.6571 | P19: =Inps!P23 -> 0.6571 | Q19: =Inps!Q23 -> 0.6571
D20: =Inps!D25 -> SG&A Expenses | E20: =Inps!E25 -> % of Revenue | M20: =Inps!M25 -> 0.14848819 | N20: =Inps!N25 -> 0.14848819 | O20: =Inps!O25 -> 0.14848819 | P20: =Inps!P25 -> 0.14848819 | Q20: =Inps!Q25 -> 0.14848819
D22: Computations
D23: =D19 -> Cost of Sales | E23: =currency -> ₦ Th's | M23: =M$14*M19 -> 3.5819802e+08 | N23: =N$14*N19 -> 4.3700159e+08 | O23: =O$14*O19 -> 5.3314194e+08 | P23: =P$14*P19 -> 6.5043316e+08 | Q23: =Q$14*Q19 -> 7.9352846e+08
D24: =D20 -> SG&A Expenses | E24: =currency -> ₦ Th's | M24: =M$14*M20 -> 80943806 | N24: =N$14*N20 -> 98751443 | O24: =O$14*O20 -> 1.2047676e+08 | P24: =P$14*P20 -> 1.4698165e+08 | Q24: =Q$14*Q20 -> 1.7931761e+08
C27: Other Profit or Loss Computations
D28: Assumptions
D29: =Inps!D28 -> Impairement | E29: =Inps!E28 -> Fixed amount | M29: =Inps!M28 -> 29043 | N29: =Inps!N28 -> 29043 | O29: =Inps!O28 -> 29043 | P29: =Inps!P28 -> 29043 | Q29: =Inps!Q28 -> 29043
D30: =Inps!D32 -> Net Foreign Exchange Loss | E30: =Inps!E32 -> Fixed amount | M30: =Inps!M32 -> 7851981 | N30: =Inps!N32 -> 7851981 | O30: =Inps!O32 -> 7851981 | P30: =Inps!P32 -> 7851981 | Q30: =Inps!Q32 -> 7851981
D32: Computations
D33: =D29 -> Impairement | E33: =currency -> ₦ Th's | M33: =M29 -> 29043 | N33: =N29 -> 29043 | O33: =O29 -> 29043 | P33: =P29 -> 29043 | Q33: =Q29 -> 29043
D34: =D30 -> Net Foreign Exchange Loss | E34: =currency -> ₦ Th's | M34: =M30 -> 7851981 | N34: =N30 -> 7851981 | O34: =O30 -> 7851981 | P34: =P30 -> 7851981 | Q34: =Q30 -> 7851981
C37: Income Tax Schedule
D38: Assumptions
D39: Statutory Tax Rate | E39: =Inps!E34 -> Statutory Tax Rate | M39: =Inps!M34 -> 0.32 | N39: =Inps!N34 -> 0.32 | O39: =Inps!O34 -> 0.32 | P39: =Inps!P34 -> 0.32 | Q39: =Inps!Q34 -> 0.32
D40: =Inps!D35 -> Reduction in EBT for Timing difference | E40: =Inps!E35 -> Implied reduction on EBT based on govt financials | M40: =Inps!M35 -> 3300000 | N40: =Inps!N35 -> 3300000 | O40: =Inps!O35 -> 3300000 | P40: =Inps!P35 -> 3300000 | Q40: =Inps!Q35 -> 3300000
D42: Accounting EBT (from P/L) | M42: =IS!M21 -> 65837999 | N42: =IS!N21 -> 89266299 | O42: =IS!O21 -> 1.1784701e+08 | P42: =IS!P21 -> 1.5594664e+08 | Q42: =IS!Q21 -> 2.0779001e+08
D43: Less: Reduction in EBT for timing difference | M43: =M40 -> 3300000 | N43: =N40 -> 3300000 | O43: =O40 -> 3300000 | P43: =P40 -> 3300000 | Q43: =Q40 -> 3300000
D44: Government Tax | M44: =M42-M43 -> 62537999 | N44: =N42-N43 -> 85966299 | O44: =O42-O43 -> 1.1454701e+08 | P44: =P42-P43 -> 1.5264664e+08 | Q44: =Q42-Q43 -> 2.0449001e+08
D46: Tax computations
D47: Current tax (cash Taxes) | M47: =M44*M39 -> 20012160 | N47: =N44*N39 -> 27509216 | O47: =O44*O39 -> 36655044 | P47: =P44*P39 -> 48846925 | Q47: =Q44*Q39 -> 65436802 | R47: What we are actually paying to the govt
D48: Deferred Tax | M48: =M49-M47 -> 1056000 | N48: =N49-N47 -> 1056000 | O48: =O49-O47 -> 1056000 | P48: =P49-P47 -> 1056000 | Q48: =Q49-Q47 -> 1056000
D49: Total Income Tax | M49: =M42*M39 -> 21068160 | N49: =N42*N39 -> 28565216 | O49: =O42*O39 -> 37711044 | P49: =P42*P39 -> 49902925 | Q49: =Q42*Q39 -> 66492802
B52: Balance Sheet Computations
C53: Calculations and Schedulesfor the balance sheet projections
B54: Operating Working Capital Computations
...

Sheet IS
B2: =company -> Nestle Nigeria
C3: Income Statement
D4: =Live_Scenario -> Live Scenario: Base Case | H4: Start Date | J4: =I5+1 -> 43831 | K4: =J5+1 -> 44197 | L4: =K5+1 -> 44562 | M4: =L5+1 -> 44927 | N4: =M5+1 -> 45292 | O4: =N5+1 -> 45658 | P4: =O5+1 -> 46023 | Q4: =P5+1 -> 46388
D5: ="Audit Check: "& Audit_check -> Audit Check: OK | H5: End Date | I5: =EOMONTH(J5,-months_in_period) -> 43830 | J5: =EOMONTH(K5,-months_in_period) -> 44196 | K5: =EOMONTH(L5,-months_in_period) -> 44561 | L5: =Date_last_historical -> 44926 | M5: =EOMONTH(L5,months_in_period) -> 45291 | N5: =EOMONTH(M5,months_in_period) -> 45657 | O5: =EOMONTH(N5,months_in_period) -> 46022 | P5: =EOMONTH(O5,months_in_period) -> 46387 | Q5: =EOMONTH(P5,months_in_period) -> 46752
D6: Actual | J6: =(J5<=Date_last_historical)*1 -> 1 | K6: =(K5<=Date_last_historical)*1 -> 1 | L6: =(L5<=Date_last_historical)*1 -> 1 | M6: =(M5<=Date_last_historical)*1 -> 0 | N6: =(N5<=Date_last_historical)*1 -> 0 | O6: =(O5<=Date_last_historical)*1 -> 0 | P6: =(P5<=Date_last_historical)*1 -> 0 | Q6: =(Q5<=Date_last_historical)*1 -> 0
D7: Forecast | J7: =(J5>=Date_last_historical)*1 -> 0 | K7: =(K5>=Date_last_historical)*1 -> 0 | L7: =(L5>Date_last_historical)*1 -> 0 | M7: =(M5>=Date_last_historical)*1 -> 1 | N7: =(N5>=Date_last_historical)*1 -> 1 | O7: =(O5>=Date_last_historical)*1 -> 1 | P7: =(P5>=Date_last_historical)*1 -> 1 | Q7: =(Q5>=Date_last_historical)*1 -> 1
D8: Description | E8: Units | F8: Inputs | I8: Row Totals | J8: Hist | K8: Hist | L8: Hist | M8: Proj | N8: Proj | O8: Proj | P8: Proj | Q8: Proj
D10: =Hist!D99 -> Revenue | J10: =Hist!J99 -> 287084087 | K10: =Hist!K99 -> 351822329 | L10: =Hist!L99 -> 446819260 | M10: =Calc!M14 -> 5.451195e+08 | N10: =Calc!N14 -> 6.6504579e+08 | O10: =Calc!O14 -> 8.1135586e+08 | P10: =Calc!P14 -> 9.8985415e+08 | Q10: =Calc!Q14 -> 1.2076221e+09
D11: =Hist!D100 -> Cost of Sales | J11: =Hist!J100 -> 162807627 | K11: =Hist!K100 -> 214296403 | L11: =Hist!L100 -> 284557646 | M11: =Calc!M23 -> 3.5819802e+08 | N11: =Calc!N23 -> 4.3700159e+08 | O11: =Calc!O23 -> 5.3314194e+08 | P11: =Calc!P23 -> 6.5043316e+08 | Q11: =Calc!Q23 -> 7.9352846e+08
D12: =Hist!D101 -> Gross Profit | J12: =J10-J11 -> 124276460 | K12: =K10-K11 -> 137525926 | L12: =L10-L11 -> 162261614 | M12: =M10-M11 -> 1.8692148e+08 | N12: =N10-N11 -> 2.280442e+08 | O12: =O10-O11 -> 2.7821392e+08 | P12: =P10-P11 -> 3.3942099e+08 | Q12: =Q10-Q11 -> 4.140936e+08
D13: =Hist!D102 -> SG&A Expenses | J13: =Hist!J102 -> 52543061 | K13: =Hist!K102 -> 57316411 | L13: =Hist!L102 -> 66347382 | M13: =Calc!M24 -> 80943806 | N13: =Calc!N24 -> 98751443 | O13: =Calc!O24 -> 1.2047676e+08 | P13: =Calc!P24 -> 1.4698165e+08 | Q13: =Calc!Q24 -> 1.7931761e+08
D14: =Hist!D103 -> EBITDA | J14: =J12-J13 -> 71733399 | K14: =K12-K13 -> 80209515 | L14: =L12-L13 -> 95914232 | M14: =M12-M13 -> 1.0597767e+08 | N14: =N12-N13 -> 1.2929276e+08 | O14: =O12-O13 -> 1.5773716e+08 | P14: =P12-P13 -> 1.9243934e+08 | Q14: =Q12-Q13 -> 2.3477599e+08
D15: =Hist!D104 -> Depreciation | J15: =Hist!J104 -> 7314816 | K15: =Hist!K104 -> 7965131 | L15: =Hist!L104 -> 9018706 | M15: =Calc!M110 -> 11648201 | N15: =Calc!N110 -> 11868368 | O15: =Calc!O110 -> 12092749 | P15: =Calc!P110 -> 12321425 | Q15: =Calc!Q110 -> 12554478
D16: =Hist!D105 -> Impairement | J16: =Hist!J105 -> 0 | K16: =Hist!K105 -> 278438 | L16: =Hist!L105 -> 29043 | M16: =Calc!M33 -> 29043 | N16: =Calc!N33 -> 29043 | O16: =Calc!O33 -> 29043 | P16: =Calc!P33 -> 29043 | Q16: =Calc!Q33 -> 29043
D17: =Hist!D106 -> EBIT | J17: =J14-J15-J16 -> 64418583 | K17: =K14-K15-K16 -> 71965946 | L17: =L14-L15-L16 -> 86866483 | M17: =M14-M15-M16 -> 94300426 | N17: =N14-N15-N16 -> 1.1739535e+08 | O17: =O14-O15-O16 -> 1.4561537e+08 | P17: =P14-P15-P16 -> 1.8008887e+08 | Q17: =Q14-Q15-Q16 -> 2.2219247e+08
D18: =Hist!D107 -> Interest income | J18: =Hist!J107 -> 646546 | K18: =Hist!K107 -> 1987042 | L18: =Hist!L107 -> 4777113 | M18: =Calc!M391 -> 4717297.2 | N18: =Calc!N391 -> 3287130.7 | O18: =Calc!O391 -> 3927819.8 | P18: =Calc!P391 -> 4758814.3 | Q18: =Calc!Q391 -> 5944666.1
D19: =Hist!D108 -> Interest Expense | J19: =Hist!J108 -> 2698404 | K19: =Hist!K108 -> 7342611 | L19: =Hist!L108 -> 12682244 | M19: =Calc!M397 -> 25327743 | N19: =Calc!N397 -> 23564196 | O19: =Calc!O397 -> 23844196 | P19: =Calc!P397 -> 21049065 | Q19: =Calc!Q397 -> 12495151
D20: =Hist!D109 -> Net Foreign Exchange Loss | J20: =Hist!J109 -> 1728282 | K20: =Hist!K109 -> 4735034 | L20: =Hist!L109 -> 7851981 | M20: =Calc!M34 -> 7851981 | N20: =Calc!N34 -> 7851981 | O20: =Calc!O34 -> 7851981 | P20: =Calc!P34 -> 7851981 | Q20: =Calc!Q34 -> 7851981
D21: =Hist!D110 -> EBT | J21: =J17+J18-J19-J20 -> 60638443 | K21: =K17+K18-K19-K20 -> 61875343 | L21: =L17+L18-L19-L20 -> 71109371 | M21: =M17+M18-M19-M20 -> 65837999 | N21: =N17+N18-N19-N20 -> 89266299 | O21: =O17+O18-O19-O20 -> 1.1784701e+08 | P21: =P17+P18-P19-P20 -> 1.5594664e+08 | Q21: =Q17+Q18-Q19-Q20 -> 2.0779001e+08
D22: =Hist!D111 -> Current Tax Expense | J22: =Hist!J111 -> 21899010 | K22: =Hist!K111 -> 21234703 | L22: =Hist!L111 -> 19877447 | M22: =Calc!M47 -> 20012160 | N22: =Calc!N47 -> 27509216 | O22: =Calc!O47 -> 36655044 | P22: =Calc!P47 -> 48846925 | Q22: =Calc!Q47 -> 65436802
D23: =Hist!D112 -> Deferred Taxes | J23: =Hist!J112 -> -472592 | K23: =Hist!K112 -> 603362 | L23: =Hist!L112 -> 2266436 | M23: =Calc!M48 -> 1056000 | N23: =Calc!N48 -> 1056000 | O23: =Calc!O48 -> 1056000 | P23: =Calc!P48 -> 1056000 | Q23: =Calc!Q48 -> 1056000
D24: =Hist!D113 -> Net Profit | J24: =J21-J22-J23 -> 39212025 | K24: =K21-K22-K23 -> 40037278 | L24: =L21-L22-L23 -> 48965488 | M24: =M21-M22-M23 -> 44769839 | N24: =N21-N22-N23 -> 60701083 | O24: =O21-O22-O23 -> 80135969 | P24: =P21-P22-P23 -> 1.0604371e+08 | Q24: =Q21-Q22-Q23 -> 1.412972e+08

Sheet BS
B2: =company -> Nestle Nigeria
C3: Balance Sheet
D4: =Live_Scenario -> Live Scenario: Base Case | H4: Start Date | J4: =I5+1 -> 43831 | K4: =J5+1 -> 44197 | L4: =K5+1 -> 44562 | M4: =L5+1 -> 44927 | N4: =M5+1 -> 45292 | O4: =N5+1 -> 45658 | P4: =O5+1 -> 46023 | Q4: =P5+1 -> 46388
D5: ="Audit Check: "& Audit_check -> Audit Check: OK | H5: End Date | I5: =EOMONTH(J5,-months_in_period) -> 43830 | J5: =EOMONTH(K5,-months_in_period) -> 44196 | K5: =EOMONTH(L5,-months_in_period) -> 44561 | L5: =Date_last_historical -> 44926 | M5: =EOMONTH(L5,months_in_period) -> 45291 | N5: =EOMONTH(M5,months_in_period) -> 45657 | O5: =EOMONTH(N5,months_in_period) -> 46022 | P5: =EOMONTH(O5,months_in_period) -> 46387 | Q5: =EOMONTH(P5,months_in_period) -> 46752
D6: Actual | J6: =(J5<=Date_last_historical)*1 -> 1 | K6: =(K5<=Date_last_historical)*1 -> 1 | L6: =(L5<=Date_last_historical)*1 -> 1 | M6: =(M5<=Date_last_historical)*1 -> 0 | N6: =(N5<=Date_last_historical)*1 -> 0 | O6: =(O5<=Date_last_historical)*1 -> 0 | P6: =(P5<=Date_last_historical)*1 -> 0 | Q6: =(Q5<=Date_last_historical)*1 -> 0
D7: Forecast | J7: =(J5>=Date_last_historical)*1 -> 0 | K7: =(K5>=Date_last_historical)*1 -> 0 | L7: =(L5>Date_last_historical)*1 -> 0 | M7: =(M5>Date_last_historical)*1 -> 1 | N7: =(N5>Date_last_historical)*1 -> 1 | O7: =(O5>Date_last_historical)*1 -> 1 | P7: =(P5>Date_last_historical)*1 -> 1 | Q7: =(Q5>Date_last_historical)*1 -> 1
D8: Description | E8: Units | F8: Inputs | I8: Row Totals | J8: Hist | K8: Hist | L8: Hist | M8: Proj | N8: Proj | O8: Proj | P8: Proj | Q8: Proj
B10: =Hist!B118 -> Assets
C11: =Hist!C119 -> Non - Current Assets
D12: =Hist!D120 -> PP&E | J12: =Hist!J120 -> 92320364 | K12: =Hist!K120 -> 103812889 | L12: =Hist!L120 -> 121715789 | M12: =Calc!M112 -> 1.2401639e+08 | N12: =Calc!N112 -> 1.2636102e+08 | O12: =Calc!O112 -> 1.2875052e+08 | P12: =Calc!P112 -> 1.3118577e+08 | Q12: =Calc!Q112 -> 1.3366762e+08
D13: =Hist!D121 -> Total Non-Current Assets | J13: =SUM(J12) -> 92320364 | K13: =SUM(K12) -> 103812889 | L13: =SUM(L12) -> 121715789 | M13: =SUM(M12) -> 1.2401639e+08 | N13: =SUM(N12) -> 1.2636102e+08 | O13: =SUM(O12) -> 1.2875052e+08 | P13: =SUM(P12) -> 1.3118577e+08 | Q13: =SUM(Q12) -> 1.3366762e+08
C15: =Hist!C123 -> Current Assets
D16: =Hist!D124 -> Trade Receivables | J16: =Hist!J124 -> 10904423 | K16: =Hist!K124 -> 4206216 | L16: =Hist!L124 -> 5493686 | M16: =Calc!M85 -> 37831293 | N16: =Calc!N85 -> 46154178 | O16: =Calc!O85 -> 56308097 | P16: =Calc!P85 -> 68695878 | Q16: =Calc!Q85 -> 83808971
D17: =Hist!D125 -> Staff Loans | J17: =Hist!J125 -> 2734089 | K17: =Hist!K125 -> 2870047 | L17: =Hist!L125 -> 2988632 | M17: =Calc!M86 -> 2866469 | N17: =Calc!N86 -> 2866469 | O17: =Calc!O86 -> 2866469 | P17: =Calc!P86 -> 2866469 | Q17: =Calc!Q86 -> 2866469
D18: =Hist!D126 -> Deposit with Company registrars for dividend | J18: =Hist!J126 -> 2724553 | K18: =Hist!K126 -> 2801222 | L18: =Hist!L126 -> 2537334 | M18: =Calc!M87 -> 2439956.2 | N18: =Calc!N87 -> 3308209 | O18: =Calc!O87 -> 4367410.3 | P18: =Calc!P87 -> 5779382.5 | Q18: =Calc!Q87 -> 7700697.7
D19: =Hist!D127 -> Advance payment to suppliers | J19: =Hist!J127 -> 23625648 | K19: =Hist!K127 -> 34263887 | L19: =Hist!L127 -> 68444339 | M19: =Calc!M88 -> 75221585 | N19: =Calc!N88 -> 91770333 | O19: =Calc!O88 -> 1.1195981e+08 | P19: =Calc!P88 -> 1.3659096e+08 | Q19: =Calc!Q88 -> 1.6664098e+08
D20: =Hist!D128 -> Other receivables | J20: =Hist!J128 -> 1982017 | K20: =Hist!K128 -> 1708116 | L20: =Hist!L128 -> 5662251 | M20: =Calc!M89 -> 1170424 | N20: =Calc!N89 -> 1170424 | O20: =Calc!O89 -> 1170424 | P20: =Calc!P89 -> 1170424 | Q20: =Calc!Q89 -> 1170424
D21: =Hist!D129 -> Total Prepayments | J21: =Hist!J129 -> 968426 | K21: =Hist!K129 -> 1093841 | L21: =Hist!L129 -> 1929038 | M21: =Calc!M90 -> 1358804 | N21: =Calc!N90 -> 1657740.9 | O21: =Calc!O90 -> 2022443.9 | P21: =Calc!P90 -> 2467381.6 | Q21: =Calc!Q90 -> 3010205.5
D22: =Hist!D130 -> Inventories | J22: =Hist!J130 -> 52222267 | K22: =Hist!K130 -> 58964125 | L22: =Hist!L130 -> 88340532 | M22: =Calc!M91 -> 68380002 | N22: =Calc!N91 -> 83423603 | O22: =Calc!O91 -> 1.017768e+08 | P22: =Calc!P91 -> 1.2416769e+08 | Q22: =Calc!Q91 -> 1.5148458e+08
D23: =Hist!D131 -> Cash and short term-deposit | J23: =Hist!J131 -> 58703209 | K23: =Hist!K131 -> 100518159 | L23: =Hist!L131 -> 117932430 | M23: =CF!M50 -> 82178268 | N23: =CF!N50 -> 98195495 | O23: =CF!O50 -> 1.1897036e+08 | P23: =CF!P50 -> 1.4861665e+08 | Q23: =CF!Q50 -> 80081560
D24: =Hist!D132 -> Total Current Assets | J24: =SUM(J16:J23) -> 153864632 | K24: =SUM(K16:K23) -> 206425613 | L24: =SUM(L16:L23) -> 293328242 | M24: =SUM(M16:M23) -> 2.714468e+08 | N24: =SUM(N16:N23) -> 3.2854645e+08 | O24: =SUM(O16:O23) -> 3.994418e+08 | P24: =SUM(P16:P23) -> 4.9035484e+08 | Q24: =SUM(Q16:Q23) -> 4.9676389e+08
D25: =Hist!D133 -> Total Assets | J25: =J13+J24 -> 246184996 | K25: =K13+K24 -> 310238502 | L25: =L13+L24 -> 415044031 | M25: =M13+M24 -> 3.9546319e+08 | N25: =N13+N24 -> 4.5490747e+08 | O25: =O13+O24 -> 5.2819233e+08 | P25: =P13+P24 -> 6.2154061e+08 | Q25: =Q13+Q24 -> 6.304315e+08
B26: =Hist!B134 -> Liability & Equity
C27: =Hist!C135 -> Equity
D28: =Hist!D136 -> Share capital | J28: =Hist!J136 -> 396328 | K28: =Hist!K136 -> 396328 | L28: =Hist!L136 -> 396328 | M28: =Calc!M118 -> 396328 | N28: =Calc!N118 -> 396328 | O28: =Calc!O118 -> 396328 | P28: =Calc!P118 -> 396328 | Q28: =Calc!Q118 -> 396328
D29: =Hist!D137 -> Share premium | J29: =Hist!J137 -> 32262 | K29: =Hist!K137 -> 32262 | L29: =Hist!L137 -> 32262 | M29: =Calc!M123 -> 32262 | N29: =Calc!N123 -> 32262 | O29: =Calc!O123 -> 32262 | P29: =Calc!P123 -> 32262 | Q29: =Calc!Q123 -> 32262
D30: =Hist!D138 -> Share based payment reserve | J30: =Hist!J138 -> 113811 | K30: =Hist!K138 -> 113456 | L30: =Hist!L138 -> 90127 | M30: =Calc!M128 -> 90127 | N30: =Calc!N128 -> 90127 | O30: =Calc!O128 -> 90127 | P30: =Calc!P128 -> 90127 | Q30: =Calc!Q128 -> 90127
D31: =Hist!D139 -> Retained earnings | J31: =Hist!J139 -> 28754583 | K31: =Hist!K139 -> 20836160 | L31: =Hist!L139 -> 29772507 | M31: =Calc!M135 -> 38726475 | N31: =Calc!N135 -> 50866692 | O31: =Calc!O135 -> 66893885 | P31: =Calc!P135 -> 88102628 | Q31: =Calc!Q135 -> 1.1636207e+08
D32: =Hist!D140 -> Total Equity | J32: =SUM(J28:J31) -> 29296984 | K32: =SUM(K28:K31) -> 21378206 | L32: =SUM(L28:L31) -> 30291224 | M32: =SUM(M28:M31) -> 39245192 | N32: =SUM(N28:N31) -> 51385409 | O32: =SUM(O28:O31) -> 67412602 | P32: =SUM(P28:P31) -> 88621345 | Q32: =SUM(Q28:Q31) -> 1.1688079e+08
C33: =Hist!C141 -> Non - Current Liabilities
D34: =Hist!D142 -> Total Loans and Borrowings | J34: =Hist!J142 -> 40211686 | K34: =Hist!K142 -> 76864802 | L34: =Hist!L142 -> 155300068 | M34: =Calc!M175 -> 152006556 | N34: =Calc!N175 -> 153006556 | O34: =Calc!O175 -> 154006556 | P34: =Calc!P175 -> 156006556 | Q34: =Calc!Q175 -> 48416847
D35: =Hist!D143 -> Employee benefits | J35: =Hist!J143 -> 4471021 | K35: =Hist!K143 -> 4038600 | L35: =Hist!L143 -> 4359648 | M35: =Calc!M93 -> 4307927 | N35: =Calc!N93 -> 4307927 | O35: =Calc!O93 -> 4307927 | P35: =Calc!P93 -> 4307927 | Q35: =Calc!Q93 -> 4307927
D36: =Hist!D144 -> Lease liabilities | J36: =Hist!J144 -> 799354 | K36: =Hist!K144 -> 467956 | L36: =Hist!L144 -> 181606 | M36: =Calc!M141 -> 181606 | N36: =Calc!N141 -> 181606 | O36: =Calc!O141 -> 181606 | P36: =Calc!P141 -> 181606 | Q36: =Calc!Q141 -> 181606
D37: =Hist!D145 -> Deferred tax liabilities | J37: =Hist!J145 -> 11984354 | K37: =Hist!K145 -> 12587716 | L37: =Hist!L145 -> 14854152 | M37: =Calc!M95 -> 15910152 | N37: =Calc!N95 -> 16966152 | O37: =Calc!O95 -> 18022152 | P37: =Calc!P95 -> 19078152 | Q37: =Calc!Q95 -> 20134152
D38: =Hist!D146 -> Total Non - Current Liabilities | J38: =SUM(J34:J37) -> 57466415 | K38: =SUM(K34:K37) -> 93959074 | L38: =SUM(L34:L37) -> 174695474 | M38: =SUM(M34:M37) -> 172406241 | N38: =SUM(N34:N37) -> 174462241 | O38: =SUM(O34:O37) -> 176518241 | P38: =SUM(P34:P37) -> 179574241 | Q38: =SUM(Q34:Q37) -> 73040532
C39: =Hist!C147 -> Current Liabilities
D40: =Hist!D148 -> Contract liabilities | J40: =Hist!J148 -> 8647246 | K40: =Hist!K148 -> 15452355 | L40: =Hist!L148 -> 16548425 | M40: =Calc!M96 -> 9703127.1 | N40: =Calc!N96 -> 11837815 | O40: =Calc!O96 -> 14442134 | P40: =Calc!P96 -> 17619404 | Q40: =Calc!Q96 -> 21495673
D41: =Hist!D149 -> Refund liabilities | J41: =Hist!J149 -> 90805 | K41: =Hist!K149 -> 78963 | L41: =Hist!L149 -> 112333 | M41: =Calc!M97 -> 708655.35 | N41: =Calc!N97 -> 864559.52 | O41: =Calc!O97 -> 1054762.6 | P41: =Calc!P97 -> 1286810.4 | Q41: =Calc!Q97 -> 1569908.7
D42: =Hist!D150 -> Current tax liabilities | J42: =Hist!J150 -> 30476315 | K42: =Hist!K150 -> 28281629 | L42: =Hist!L150 -> 26208706 | M42: =Calc!M98 -> 27737549 | N42: =Calc!N98 -> 37607892 | O42: =Calc!O98 -> 49648947 | P42: =Calc!P98 -> 65700319 | Q42: =Calc!Q98 -> 87541930
D43: =Hist!D151 -> Provisions | J43: =Hist!J151 -> 3691991 | K43: =Hist!K151 -> 2701498 | L43: =Hist!L151 -> 1026008 | M43: =Calc!M99 -> 1389181.8 | N43: =Calc!N99 -> 1883518.9 | O43: =Calc!O99 -> 2486572 | P43: =Calc!P99 -> 3290474.1 | Q43: =Calc!Q99 -> 4384369.2
...

Sheet CF
B2: =company -> Nestle Nigeria
C3: Cash Flow Statement
D4: =Live_Scenario -> Live Scenario: Base Case | H4: Start Date | J4: =I5+1 -> 43831 | K4: =J5+1 -> 44197 | L4: =K5+1 -> 44562 | M4: =L5+1 -> 44927 | N4: =M5+1 -> 45292 | O4: =N5+1 -> 45658 | P4: =O5+1 -> 46023 | Q4: =P5+1 -> 46388
D5: ="Audit Check: "& Audit_check -> Audit Check: OK | H5: End Date | I5: =EOMONTH(J5,-months_in_period) -> 43830 | J5: =EOMONTH(K5,-months_in_period) -> 44196 | K5: =EOMONTH(L5,-months_in_period) -> 44561 | L5: =Date_last_historical -> 44926 | M5: =EOMONTH(L5,months_in_period) -> 45291 | N5: =EOMONTH(M5,months_in_period) -> 45657 | O5: =EOMONTH(N5,months_in_period) -> 46022 | P5: =EOMONTH(O5,months_in_period) -> 46387 | Q5: =EOMONTH(P5,months_in_period) -> 46752
D6: Actual | J6: =(J5<=Date_last_historical)*1 -> 1 | K6: =(K5<=Date_last_historical)*1 -> 1 | L6: =(L5<=Date_last_historical)*1 -> 1 | M6: =(M5<=Date_last_historical)*1 -> 0 | N6: =(N5<=Date_last_historical)*1 -> 0 | O6: =(O5<=Date_last_historical)*1 -> 0 | P6: =(P5<=Date_last_historical)*1 -> 0 | Q6: =(Q5<=Date_last_historical)*1 -> 0
D7: Forecast | J7: =(J5>=Date_last_historical)*1 -> 0 | K7: =(K5>=Date_last_historical)*1 -> 0 | L7: =(L5>Date_last_historical)*1 -> 0 | M7: =(M5>=Date_last_historical)*1 -> 1 | N7: =(N5>=Date_last_historical)*1 -> 1 | O7: =(O5>=Date_last_historical)*1 -> 1 | P7: =(P5>=Date_last_historical)*1 -> 1 | Q7: =(Q5>=Date_last_historical)*1 -> 1
D8: Description | E8: Units | F8: Inputs | I8: Row Totals | J8: Hist | K8: Hist | L8: Hist | M8: Proj | N8: Proj | O8: Proj | P8: Proj | Q8: Proj
C10: Cash Flow from Operations
D11: =IS!D17 -> EBIT | M11: =IS!M17 -> 94300426 | N11: =IS!N17 -> 1.1739535e+08 | O11: =IS!O17 -> 1.4561537e+08 | P11: =IS!P17 -> 1.8008887e+08 | Q11: =IS!Q17 -> 2.2219247e+08
D12: Adjusting for non-cash expense
D13: =IS!D15 -> Depreciation | M13: =IS!M15 -> 11648201 | N13: =IS!N15 -> 11868368 | O13: =IS!O15 -> 12092749 | P13: =IS!P15 -> 12321425 | Q13: =IS!Q15 -> 12554478
D14: =IS!D16 -> Impairement | M14: =IS!M16 -> 29043 | N14: =IS!N16 -> 29043 | O14: =IS!O16 -> 29043 | P14: =IS!P16 -> 29043 | Q14: =IS!Q16 -> 29043
D15: EBITDA | M15: =M11+M13+M14 -> 1.0597767e+08 | N15: =N11+N13+N14 -> 1.2929276e+08 | O15: =O11+O13+O14 -> 1.5773716e+08 | P15: =P11+P13+P14 -> 1.9243934e+08 | Q15: =Q11+Q13+Q14 -> 2.3477599e+08
D16: =Calc!D104 -> Change in OWC | M16: =Calc!M104 -> -35271144 | N16: =Calc!N104 -> 2988080.9 | O16: =Calc!O104 -> 3412404.4 | P16: =Calc!P104 -> 5240529.3 | Q16: =Calc!Q104 -> 8334487.8
D17: Adjusting for non-cash tax expense
D18: =IS!D23 -> Deferred Taxes | M18: =-IS!M23 -> -1056000 | N18: =-IS!N23 -> -1056000 | O18: =-IS!O23 -> -1056000 | P18: =-IS!P23 -> -1056000 | Q18: =-IS!Q23 -> -1056000
D19: Financing Operations
D20: =IS!D18 -> Interest income | M20: =IS!M18 -> 4717297.2 | N20: =IS!N18 -> 3287130.7 | O20: =IS!O18 -> 3927819.8 | P20: =IS!P18 -> 4758814.3 | Q20: =IS!Q18 -> 5944666.1
D21: =IS!D19 -> Interest Expense | M21: =-IS!M19 -> -25327743 | N21: =-IS!N19 -> -23564196 | O21: =-IS!O19 -> -23844196 | P21: =-IS!P19 -> -21049065 | Q21: =-IS!Q19 -> -12495151
D22: =IS!D20 -> Net Foreign Exchange Loss | M22: =-IS!M20 -> -7851981 | N22: =-IS!N20 -> -7851981 | O22: =-IS!O20 -> -7851981 | P22: =-IS!P20 -> -7851981 | Q22: =-IS!Q20 -> -7851981
D24: =IS!D22 -> Current Tax Expense | M24: =-IS!M22 -> -20012160 | N24: =-IS!N22 -> -27509216 | O24: =-IS!O22 -> -36655044 | P24: =-IS!P22 -> -48846925 | Q24: =-IS!Q22 -> -65436802
D26: Total Cash Flow from Operations | M26: =SUM(M15:M24) -> 21175940 | N26: =SUM(N15:N24) -> 75586576 | O26: =SUM(O15:O24) -> 95670166 | P26: =SUM(P15:P24) -> 1.2363471e+08 | Q26: =SUM(Q15:Q24) -> 1.6221521e+08
C28: Cash Flow from Investing
D29: =Calc!D109 -> Capex | M29: =-Calc!M109 -> -13977841 | N29: =-Calc!N109 -> -14242042 | O29: =-Calc!O109 -> -14511299 | P29: =-Calc!P109 -> -14785710 | Q29: =-Calc!Q109 -> -15065373
D31: Total Cash Flow from Investing | M31: =M29 -> -13977841 | N31: =N29 -> -14242042 | O31: =O29 -> -14511299 | P31: =P29 -> -14785710 | Q31: =Q29 -> -15065373
C33: Cash Flow from Financing
D35: ="Change in "& Calc!C115 -> Change in Share capital | M35: =Calc!M117 -> 0 | N35: =Calc!N117 -> 0 | O35: =Calc!O117 -> 0 | P35: =Calc!P117 -> 0 | Q35: =Calc!Q117 -> 0
D36: ="Change in "&Calc!C120 -> Change in Share premium | M36: =Calc!M122 -> 0 | N36: =Calc!N122 -> 0 | O36: =Calc!O122 -> 0 | P36: =Calc!P122 -> 0 | Q36: =Calc!Q122 -> 0
D37: ="Change in "& Calc!C125 -> Change in Share based payment reserve | M37: =Calc!M127 -> 0 | N37: =Calc!N127 -> 0 | O37: =Calc!O127 -> 0 | P37: =Calc!P127 -> 0 | Q37: =Calc!Q127 -> 0
D38: =Calc!D173 -> Total New Debt Issued | M38: =Calc!M173 -> 5000000 | N38: =Calc!N173 -> 1000000 | O38: =Calc!O173 -> 6000000 | P38: =Calc!P173 -> 3000000 | Q38: =Calc!Q173 -> 2000000
D39: =Calc!D174 -> Total Repayments | M39: =-Calc!M174 -> -8293512 | N39: =-Calc!N174 -> 0 | O39: =-Calc!O174 -> -5000000 | P39: =-Calc!P174 -> -1000000 | Q39: =-Calc!Q174 -> -109589709
D40: =Calc!D162 -> Dividend Paid | M40: =-Calc!M162 -> -39658749 | N40: =-Calc!N162 -> -46327306 | O40: =-Calc!O162 -> -61384004 | P40: =-Calc!P162 -> -81202706 | Q40: =-Calc!Q162 -> -1.0809522e+08
D41: Overdraft - New Issue (or Repayment) | M41: =Calc!M424 -> 0 | N41: =Calc!N424 -> 0 | O41: =Calc!O424 -> 0 | P41: =Calc!P424 -> 0 | Q41: =Calc!Q424 -> 0
D43: Total Cash Flow from Financing | M43: =SUM(M35:M41) -> -42952261 | N43: =SUM(N35:N41) -> -45327306 | O43: =SUM(O35:O41) -> -60384004 | P43: =SUM(P35:P41) -> -79202706 | Q43: =SUM(Q35:Q41) -> -2.1568493e+08
D45: Total Cash Generated in the Year | M45: =M26+M31+M43 -> -35754162 | N45: =N26+N31+N43 -> 16017227 | O45: =O26+O31+O43 -> 20774862 | P45: =P26+P31+P43 -> 29646296 | Q45: =Q26+Q31+Q43 -> -68535093
C47: Cash Schedule
D48: Beginning Balance | M48: =L50 -> 117932430 | N48: =M50 -> 82178268 | O48: =N50 -> 98195495 | P48: =O50 -> 1.1897036e+08 | Q48: =P50 -> 1.4861665e+08
D49: =D45 -> Total Cash Generated in the Year | M49: =M45 -> -35754162 | N49: =N45 -> 16017227 | O49: =O45 -> 20774862 | P49: =P45 -> 29646296 | Q49: =Q45 -> -68535093
D50: Ending Balance | L50: =BS!L23 -> 117932430 | M50: =SUM(M48:M49) -> 82178268 | N50: =SUM(N48:N49) -> 98195495 | O50: =SUM(O48:O49) -> 1.1897036e+08 | P50: =SUM(P48:P49) -> 1.4861665e+08 | Q50: =SUM(Q48:Q49) -> 80081560
E58: Note: Cash balances can not be less than 0 because the overdraft schedule will take care of it by borrowing more cash

Sheet Ratios
B2: =company -> Nestle Nigeria
C3: Ratio Analysis
D4: =Live_Scenario -> Live Scenario: Base Case | H4: Start Date | J4: =I5+1 -> 43831 | K4: =J5+1 -> 44197 | L4: =K5+1 -> 44562 | M4: =L5+1 -> 44927 | N4: =M5+1 -> 45292 | O4: =N5+1 -> 45658 | P4: =O5+1 -> 46023 | Q4: =P5+1 -> 46388
D5: ="Audit Check: "& Audit_check -> Audit Check: OK | H5: End Date | I5: =EOMONTH(J5,-months_in_period) -> 43830 | J5: =EOMONTH(K5,-months_in_period) -> 44196 | K5: =EOMONTH(L5,-months_in_period) -> 44561 | L5: =Date_last_historical -> 44926 | M5: =EOMONTH(L5,months_in_period) -> 45291 | N5: =EOMONTH(M5,months_in_period) -> 45657 | O5: =EOMONTH(N5,months_in_period) -> 46022 | P5: =EOMONTH(O5,months_in_period) -> 46387 | Q5: =EOMONTH(P5,months_in_period) -> 46752
D6: Actual | J6: =(J5<=Date_last_historical)*1 -> 1 | K6: =(K5<=Date_last_historical)*1 -> 1 | L6: =(L5<=Date_last_historical)*1 -> 1 | M6: =(M5<=Date_last_historical)*1 -> 0 | N6: =(N5<=Date_last_historical)*1 -> 0 | O6: =(O5<=Date_last_historical)*1 -> 0 | P6: =(P5<=Date_last_historical)*1 -> 0 | Q6: =(Q5<=Date_last_historical)*1 -> 0
D7: Forecast | J7: =(J5>=Date_last_historical)*1 -> 0 | K7: =(K5>=Date_last_historical)*1 -> 0 | L7: =(L5>Date_last_historical)*1 -> 0 | M7: =(M5>=Date_last_historical)*1 -> 1 | N7: =(N5>=Date_last_historical)*1 -> 1 | O7: =(O5>=Date_last_historical)*1 -> 1 | P7: =(P5>=Date_last_historical)*1 -> 1 | Q7: =(Q5>=Date_last_historical)*1 -> 1
D8: Description | E8: Units | F8: Inputs | I8: Row Totals | J8: Hist | K8: Hist | L8: Hist | M8: Proj | N8: Proj | O8: Proj | P8: Proj | Q8: Proj
B9: Profitability Ratios
D10: Gross Profit Margin | J10: =IS!J12/IS!J10 -> 0.43289219 | K10: =IS!K12/IS!K10 -> 0.39089596 | L10: =IS!L12/IS!L10 -> 0.36314821 | M10: =IS!M12/IS!M10 -> 0.3429 | N10: =IS!N12/IS!N10 -> 0.3429 | O10: =IS!O12/IS!O10 -> 0.3429 | P10: =IS!P12/IS!P10 -> 0.3429 | Q10: =IS!Q12/IS!Q10 -> 0.3429
D11: Operating Profit Margin | J11: =IS!J14/IS!J10 -> 0.24986895 | K11: =IS!K14/IS!K10 -> 0.22798301 | L11: =IS!L14/IS!L10 -> 0.21466002 | M11: =IS!M14/IS!M10 -> 0.19441181 | N11: =IS!N14/IS!N10 -> 0.19441181 | O11: =IS!O14/IS!O10 -> 0.19441181 | P11: =IS!P14/IS!P10 -> 0.19441181 | Q11: =IS!Q14/IS!Q10 -> 0.19441181
D12: Net Profit Margin | J12: =IS!J24/IS!J10 -> 0.13658725 | K12: =IS!K24/IS!K10 -> 0.11379971 | L12: =IS!L24/IS!L10 -> 0.10958679 | M12: =IS!M24/IS!M10 -> 0.082128487 | N12: =IS!N24/IS!N10 -> 0.09127354 | O12: =IS!O24/IS!O10 -> 0.098767968 | P12: =IS!P24/IS!P10 -> 0.10713065 | Q12: =IS!Q24/IS!Q10 -> 0.11700449
D13: Return on Assets
D14: Return on Equity
D15: Return on Capital Employed | J15: =IS!J21/(BS!J25-BS!J48) -> 0.69889428 | K15: =IS!K21/(BS!K25-BS!K48) -> 0.53647306 | L15: =IS!L21/(BS!L25-BS!L48) -> 0.34689749 | M15: =IS!M21/(BS!M25-BS!M48) -> 0.31106805 | N15: =IS!N21/(BS!N25-BS!N48) -> 0.39525007 | O15: =IS!O21/(BS!O25-BS!O48) -> 0.48311649 | P15: =IS!P21/(BS!P25-BS!P48) -> 0.58146609 | Q15: =IS!Q21/(BS!Q25-BS!Q48) -> 1.0940847
B17: Liquidity Ratios
D18: Current Ratio | J18: =BS!J24/BS!J48 -> 0.96514296 | K18: =BS!K24/BS!K48 -> 1.0591294 | L18: =BS!L24/BS!L48 -> 1.3964199 | M18: =BS!M24/BS!M48 -> 1.4767652 | N18: =BS!N24/BS!N48 -> 1.434326 | O18: =BS!O24/BS!O48 -> 1.4051914 | P18: =BS!P24/BS!P48 -> 1.3877508 | Q18: =BS!Q24/BS!Q48 -> 1.1277012
D19: Quick Ratio | J19: =(BS!J24-BS!J22)/BS!J48 -> 0.63756961 | K19: =(BS!K24-BS!K22)/BS!K48 -> 0.75659602 | L19: =(BS!L24-BS!L22)/BS!L48 -> 0.97586553 | M19: =(BS!M24-BS!M22)/BS!M48 -> 1.1047542 | N19: =(BS!N24-BS!N22)/BS!N48 -> 1.0701259 | O19: =(BS!O24-BS!O22)/BS!O48 -> 1.0471521 | P19: =(BS!P24-BS!P22)/BS!P48 -> 1.0363444 | Q19: =(BS!Q24-BS!Q22)/BS!Q48 -> 0.78381684
D20: Cash Ratio | J20: =BS!J23/BS!J48 -> 0.3682262 | K20: =BS!K23/BS!K48 -> 0.51573899 | L20: =BS!L23/BS!L48 -> 0.56142972 | M20: =BS!M23/BS!M48 -> 0.44707841 | N20: =BS!N23/BS!N48 -> 0.42868931 | O20: =BS!O23/BS!O48 -> 0.41852437 | P20: =BS!P23/BS!P48 -> 0.42059926 | Q20: =BS!Q23/BS!Q48 -> 0.18179275
B22: Leverage Ratios
D23: Debt-to-Equity Ratio | L23: =Calc!L175/BS!L32 -> 5.1268997 | M23: =Calc!M175/BS!M32 -> 3.873253 | N23: =Calc!N175/BS!N32 -> 2.9776265 | O23: =Calc!O175/BS!O32 -> 2.2845366 | P23: =Calc!P175/BS!P32 -> 1.7603722 | Q23: =Calc!Q175/BS!Q32 -> 0.41424128
D24: Debt Ratio | L24: =Calc!L175/BS!L25 -> 0.37417733 | M24: =Calc!M175/BS!M25 -> 0.384376 | N24: =Calc!N175/BS!N25 -> 0.33634655 | O24: =Calc!O175/BS!O25 -> 0.29157288 | P24: =Calc!P175/BS!P25 -> 0.25099978 | Q24: =Calc!Q175/BS!Q25 -> 0.076799536
D25: Interest Coverage Ratio | J25: =IS!J11/IS!J13 -> 3.0985562 | K25: =IS!K11/IS!K13 -> 3.7388315 | L25: =IS!L11/IS!L13 -> 4.2889054 | M25: =IS!M11/IS!M13 -> 4.4252678 | N25: =IS!N11/IS!N13 -> 4.4252678 | O25: =IS!O11/IS!O13 -> 4.4252678 | P25: =IS!P11/IS!P13 -> 4.4252678 | Q25: =IS!Q11/IS!Q13 -> 4.4252678
D26: Equity Ratio | J26: =BS!J32/BS!J25 -> 0.11900394 | K26: =BS!K32/BS!K25 -> 0.068908939 | L26: =BS!L32/BS!L25 -> 0.072983158 | M26: =BS!M32/BS!M25 -> 0.099238546 | N26: =BS!N32/BS!N25 -> 0.11295794 | O26: =BS!O32/BS!O25 -> 0.12762889 | P26: =BS!P32/BS!P25 -> 0.14258336 | Q26: =BS!Q32/BS!Q25 -> 0.18539807
B28: Efficiency Ratios
B32: Market Ratios

Sheet Vals
B2: =company -> Nestle Nigeria
C3: Valuation Analysis
D4: =Live_Scenario -> Live Scenario: Base Case | H4: Start Date | J4: =I5+1 -> 43831 | K4: =J5+1 -> 44197 | L4: =K5+1 -> 44562 | M4: =L5+1 -> 44927 | N4: =M5+1 -> 45292 | O4: =N5+1 -> 45658 | P4: =O5+1 -> 46023 | Q4: =P5+1 -> 46388
D5: ="Audit Check: "& Audit_check -> Audit Check: OK | H5: End Date | I5: =EOMONTH(J5,-months_in_period) -> 43830 | J5: =EOMONTH(K5,-months_in_period) -> 44196 | K5: =EOMONTH(L5,-months_in_period) -> 44561 | L5: =Date_last_historical -> 44926 | M5: =EOMONTH(L5,months_in_period) -> 45291 | N5: =EOMONTH(M5,months_in_period) -> 45657 | O5: =EOMONTH(N5,months_in_period) -> 46022 | P5: =EOMONTH(O5,months_in_period) -> 46387 | Q5: =EOMONTH(P5,months_in_period) -> 46752
D6: Actual | J6: =(J5<=Date_last_historical)*1 -> 1 | K6: =(K5<=Date_last_historical)*1 -> 1 | L6: =(L5<=Date_last_historical)*1 -> 1 | M6: =(M5<=Date_last_historical)*1 -> 0 | N6: =(N5<=Date_last_historical)*1 -> 0 | O6: =(O5<=Date_last_historical)*1 -> 0 | P6: =(P5<=Date_last_historical)*1 -> 0 | Q6: =(Q5<=Date_last_historical)*1 -> 0
D7: Forecast | J7: =(J5>=Date_last_historical)*1 -> 0 | K7: =(K5>=Date_last_historical)*1 -> 0 | L7: =(L5>Date_last_historical)*1 -> 0 | M7: =(M5>=Date_last_historical)*1 -> 1 | N7: =(N5>=Date_last_historical)*1 -> 1 | O7: =(O5>=Date_last_historical)*1 -> 1 | P7: =(P5>=Date_last_historical)*1 -> 1 | Q7: =(Q5>=Date_last_historical)*1 -> 1
D8: Description | E8: Units | F8: Inputs | I8: Row Totals | J8: Hist | K8: Hist | L8: Hist | M8: Proj | N8: Proj | O8: Proj | P8: Proj | Q8: Proj
